Workbook
Name _DISC1: #REF!
Name _DISC1: #REF!
Name _DISC1: #REF!
Name _DISC1: #REF!
Name _LT: [1]OTHER!$A$1:$B$7
Name _SREDA: [1]OTHER!$E$1:$F$3
Name p_3p_c_c: OFFSET('[2]Калькулятор бюджета'!$J$82,1,0,COUNTA('[2]Калькулятор бюджета'!$B$82:$B$92)-1,1)
Name p_3p_c_c: OFFSET('Калькулятор бюджета по ЦФО'!$K$69,1,0,COUNTA('Калькулятор бюджета по ЦФО'!$B$69:$B$79)-1,1)
Name p_3p_c_c: OFFSET('[3]Калькулятор бюджета по этапам'!$K$75,1,0,COUNTA('[3]Калькулятор бюджета по этапам'!$B$75:$B$86)-1,1)
Name p_3p_c_c: OFFSET('[4]Калькулятор бюджета'!$J$72,1,0,COUNTA('[4]Калькулятор бюджета'!$B$72:$B$82)-1,1)
Name p_3p_c_c: OFFSET('[2]Калькулятор бюджета'!$J$82,1,0,COUNTA('[2]Калькулятор бюджета'!$B$82:$B$92)-1,1)
Name p_3p_c_c: OFFSET('Калькулятор бюджета по этапам'!$K$75,1,0,COUNTA('Калькулятор бюджета по этапам'!$B$75:$B$86)-1,1)
Name p_3p_c_eff: OFFSET('[2]Калькулятор бюджета'!$H$82,1,0,COUNTA('[2]Калькулятор бюджета'!$B$82:$B$92)-1,1)
Name p_3p_c_eff: OFFSET('Калькулятор бюджета по ЦФО'!$I$69,1,0,COUNTA('Калькулятор бюджета по ЦФО'!$B$69:$B$79)-1,1)
Name p_3p_c_eff: OFFSET('[3]Калькулятор бюджета по этапам'!$I$75,1,0,COUNTA('[3]Калькулятор бюджета по этапам'!$B$75:$B$86)-1,1)
Name p_3p_c_eff: OFFSET('[4]Калькулятор бюджета'!$H$72,1,0,COUNTA('[4]Калькулятор бюджета'!$B$72:$B$82)-1,1)
Name p_3p_c_eff: OFFSET('[2]Калькулятор бюджета'!$H$82,1,0,COUNTA('[2]Калькулятор бюджета'!$B$82:$B$92)-1,1)
Name p_3p_c_eff: OFFSET('Калькулятор бюджета по этапам'!$I$75,1,0,COUNTA('Калькулятор бюджета по этапам'!$B$75:$B$86)-1,1)
Name p_3p_c_ph: OFFSET('[2]Калькулятор бюджета'!$B$82,1,0,COUNTA('[2]Калькулятор бюджета'!$B$82:$B$92)-1,1)
Name p_3p_c_ph: OFFSET('Калькулятор бюджета по ЦФО'!$B$69,1,0,COUNTA('Калькулятор бюджета по ЦФО'!$B$69:$B$79)-1,1)
Name p_3p_c_ph: OFFSET('[3]Калькулятор бюджета по этапам'!$B$75,1,0,COUNTA('[3]Калькулятор бюджета по этапам'!$B$75:$B$86)-1,1)
Name p_3p_c_ph: OFFSET('[4]Калькулятор бюджета'!$B$72,1,0,COUNTA('[4]Калькулятор бюджета'!$B$72:$B$82)-1,1)
Name p_3p_c_ph: OFFSET('[2]Калькулятор бюджета'!$B$82,1,0,COUNTA('[2]Калькулятор бюджета'!$B$82:$B$92)-1,1)
Name p_3p_c_ph: OFFSET('Калькулятор бюджета по этапам'!$B$75,1,0,COUNTA('Калькулятор бюджета по этапам'!$B$75:$B$86)-1,1)
Name p_3p_c_r: OFFSET('[2]Калькулятор бюджета'!$S$82,1,0,COUNTA('[2]Калькулятор бюджета'!$B$82:$B$92)-1,1)
Name p_3p_c_r: OFFSET('Калькулятор бюджета по ЦФО'!$N$69,1,0,COUNTA('Калькулятор бюджета по ЦФО'!$B$69:$B$79)-1,1)
Name p_3p_c_r: OFFSET('[3]Калькулятор бюджета по этапам'!$N$75,1,0,COUNTA('[3]Калькулятор бюджета по этапам'!$B$75:$B$86)-1,1)
Name p_3p_c_r: OFFSET('[4]Калькулятор бюджета'!$M$72,1,0,COUNTA('[4]Калькулятор бюджета'!$B$72:$B$82)-1,1)
Name p_3p_c_r: OFFSET('[2]Калькулятор бюджета'!$S$82,1,0,COUNTA('[2]Калькулятор бюджета'!$B$82:$B$92)-1,1)
Name p_3p_c_r: OFFSET('Калькулятор бюджета по этапам'!$N$75,1,0,COUNTA('Калькулятор бюджета по этапам'!$B$75:$B$86)-1,1)
Name p_3p_o_c: OFFSET('[2]Калькулятор бюджета'!$G$119,1,0,COUNTA('[2]Калькулятор бюджета'!$B$119:$B$123)-1,1)
Name p_3p_o_c: OFFSET('Калькулятор бюджета по ЦФО'!$H$106,1,0,COUNTA('Калькулятор бюджета по ЦФО'!$B$106:$B$110)-1,1)
Name p_3p_o_c: OFFSET('[3]Калькулятор бюджета по этапам'!$H$115,1,0,COUNTA('[3]Калькулятор бюджета по этапам'!$B$115:$B$120)-1,1)
Name p_3p_o_c: OFFSET('[4]Калькулятор бюджета'!$G$109,1,0,COUNTA('[4]Калькулятор бюджета'!$B$109:$B$113)-1,1)
Name p_3p_o_c: OFFSET('[2]Калькулятор бюджета'!$G$119,1,0,COUNTA('[2]Калькулятор бюджета'!$B$119:$B$123)-1,1)
Name p_3p_o_c: OFFSET('Калькулятор бюджета по этапам'!$H$115,1,0,COUNTA('Калькулятор бюджета по этапам'!$B$115:$B$120)-1,1)
Name p_3p_o_ph: OFFSET('[2]Калькулятор бюджета'!$B$119,1,0,COUNTA('[2]Калькулятор бюджета'!$B$119:$B$123)-1,1)
Name p_3p_o_ph: OFFSET('Калькулятор бюджета по ЦФО'!$B$106,1,0,COUNTA('Калькулятор бюджета по ЦФО'!$B$106:$B$110)-1,1)
Name p_3p_o_ph: OFFSET('[3]Калькулятор бюджета по этапам'!$B$115,1,0,COUNTA('[3]Калькулятор бюджета по этапам'!$B$115:$B$120)-1,1)
Name p_3p_o_ph: OFFSET('[4]Калькулятор бюджета'!$B$109,1,0,COUNTA('[4]Калькулятор бюджета'!$B$109:$B$113)-1,1)
Name p_3p_o_ph: OFFSET('[2]Калькулятор бюджета'!$B$119,1,0,COUNTA('[2]Калькулятор бюджета'!$B$119:$B$123)-1,1)
Name p_3p_o_ph: OFFSET('Калькулятор бюджета по этапам'!$B$115,1,0,COUNTA('Калькулятор бюджета по этапам'!$B$115:$B$120)-1,1)
Name p_3p_o_r: OFFSET('[2]Калькулятор бюджета'!$I$119,1,0,COUNTA('[2]Калькулятор бюджета'!$B$119:$B$123)-1,1)
Name p_3p_o_r: OFFSET('Калькулятор бюджета по ЦФО'!$J$106,1,0,COUNTA('Калькулятор бюджета по ЦФО'!$B$106:$B$110)-1,1)
Name p_3p_o_r: OFFSET('[3]Калькулятор бюджета по этапам'!$J$115,1,0,COUNTA('[3]Калькулятор бюджета по этапам'!$B$115:$B$120)-1,1)
Name p_3p_o_r: OFFSET('[4]Калькулятор бюджета'!$I$109,1,0,COUNTA('[4]Калькулятор бюджета'!$B$109:$B$113)-1,1)
Name p_3p_o_r: OFFSET('[2]Калькулятор бюджета'!$I$119,1,0,COUNTA('[2]Калькулятор бюджета'!$B$119:$B$123)-1,1)
Name p_3p_o_r: OFFSET('Калькулятор бюджета по этапам'!$J$115,1,0,COUNTA('Калькулятор бюджета по этапам'!$B$115:$B$120)-1,1)
Name p_3p_t_c: OFFSET('[2]Калькулятор бюджета'!$F$147,1,0,COUNTA('[2]Калькулятор бюджета'!$B$147:$B$154)-1,1)
Name p_3p_t_c: OFFSET('Калькулятор бюджета по ЦФО'!$G$134,1,0,COUNTA('Калькулятор бюджета по ЦФО'!$B$134:$B$141)-1,1)
Name p_3p_t_c: OFFSET('[3]Калькулятор бюджета по этапам'!$G$146,1,0,COUNTA('[3]Калькулятор бюджета по этапам'!$B$146:$B$154)-1,1)
Name p_3p_t_c: OFFSET('[4]Калькулятор бюджета'!$F$137,1,0,COUNTA('[4]Калькулятор бюджета'!$B$137:$B$144)-1,1)
Name p_3p_t_c: OFFSET('[2]Калькулятор бюджета'!$F$147,1,0,COUNTA('[2]Калькулятор бюджета'!$B$147:$B$154)-1,1)
Name p_3p_t_c: OFFSET('Калькулятор бюджета по этапам'!$G$146,1,0,COUNTA('Калькулятор бюджета по этапам'!$B$146:$B$154)-1,1)
Name p_3p_t_ph: OFFSET('[2]Калькулятор бюджета'!$B$147,1,0,COUNTA('[2]Калькулятор бюджета'!$B$147:$B$154)-1,1)
Name p_3p_t_ph: OFFSET('Калькулятор бюджета по ЦФО'!$B$134,1,0,COUNTA('Калькулятор бюджета по ЦФО'!$B$134:$B$141)-1,1)
Name p_3p_t_ph: OFFSET('[3]Калькулятор бюджета по этапам'!$B$146,1,0,COUNTA('[3]Калькулятор бюджета по этапам'!$B$146:$B$154)-1,1)
Name p_3p_t_ph: OFFSET('[4]Калькулятор бюджета'!$B$137,1,0,COUNTA('[4]Калькулятор бюджета'!$B$137:$B$144)-1,1)
Name p_3p_t_ph: OFFSET('[2]Калькулятор бюджета'!$B$147,1,0,COUNTA('[2]Калькулятор бюджета'!$B$147:$B$154)-1,1)
Name p_3p_t_ph: OFFSET('Калькулятор бюджета по этапам'!$B$146,1,0,COUNTA('Калькулятор бюджета по этапам'!$B$146:$B$154)-1,1)

Sheet Ставки и расходы
C1: Информация о проекте
C2: Имя проекта:
C3: Код проекта: | D3: ПРЕ
C4: Заказчик:
C5: РП: | D5: Осипов Алексей Владимирович
C6: Дата старта
C7: Дата завершения | D7: Длительность 13 мес.
C9: 1.1. Позиции и ставки
B10: Кадровый грейд (справочное соответствие) | C10: Позиция | D10: Ставка себестоимости ч/д, руб. | E10: Минимальная внешняя ставка ч/д, руб. | F10: Рекомендуемая внешняя ставка ч/д, руб. | G10: Расчетная внешняя ставка ч/д, руб. | H10: Скидка | I10: Скидка (внутренняя ставка)
B11: 17-18 кадровый грейд | C11: 6. Sales Grade | D11: 39120 | E11: 60240 | F11: 70080 | G11: 70080 | H11: 0 | I11: 0
B12: 16 кадровый грейд | C12: 5. Sales Grade | D12: 34039 | E12: 51120 | F12: 53040 | G12: 53040
B13: 15 кадровый грейд | C13: 4. Sales Grade | D13: 30017 | E13: 41760 | F13: 41760 | G13: 41760
B14: 14 кадровый грейд | C14: 3. Sales Grade | D14: 22711 | E14: 31280 | F14: 31280 | G14: 31280
B15: 13 кадровый грейд | C15: 2. Sales Grade | D15: 17589 | E15: 23120 | F15: 23120 | G15: 23120
B16: 10-12 кадровый грейд | C16: 1. Sales Grade | D16: 11280 | E16: 14480 | F16: 14480 | G16: 14480
C20: 1.2 Команда
B21: Подразделение (ЦК/ЦФО/МВЗ) | C21: ФИО | D21: Роль | E21: Позиция | F21: Внутренняя ставка ч/д, руб. | G21: Внешняя ставка ч/д, руб. | H21: Наценка (%)
F22: =IFERROR(VLOOKUP(E22,$C$11:$F$16,2,FALSE)*(1-$I$11),0) -> 0 | G22: =IFERROR(VLOOKUP(E22,$C$11:$G$16,5,FALSE)*(1-$H$11),0) -> 0 | H22: =IF(G22>0,G22/F22-1,0) -> 0
F23: =IFERROR(VLOOKUP(E23,$C$11:$F$16,2,FALSE)*(1-$I$11),0) -> 0 | G23: =IFERROR(VLOOKUP(E23,$C$11:$G$16,5,FALSE)*(1-$H$11),0) -> 0 | H23: =IF(G23>0,G23/F23-1,0) -> 0
F24: =IFERROR(VLOOKUP(E24,$C$11:$F$16,2,FALSE)*(1-$I$11),0) -> 0 | G24: =IFERROR(VLOOKUP(E24,$C$11:$G$16,5,FALSE)*(1-$H$11),0) -> 0 | H24: =IF(G24>0,G24/F24-1,0) -> 0
F25: =IFERROR(VLOOKUP(E25,$C$11:$F$16,2,FALSE)*(1-$I$11),0) -> 0 | G25: =IFERROR(VLOOKUP(E25,$C$11:$G$16,5,FALSE)*(1-$H$11),0) -> 0 | H25: =IF(G25>0,G25/F25-1,0) -> 0
F26: =IFERROR(VLOOKUP(E26,$C$11:$F$16,2,FALSE)*(1-$I$11),0) -> 0 | G26: =IFERROR(VLOOKUP(E26,$C$11:$G$16,5,FALSE)*(1-$H$11),0) -> 0 | H26: =IF(G26>0,G26/F26-1,0) -> 0
F27: =IFERROR(VLOOKUP(E27,$C$11:$F$16,2,FALSE)*(1-$I$11),0) -> 0 | G27: =IFERROR(VLOOKUP(E27,$C$11:$G$16,5,FALSE)*(1-$H$11),0) -> 0 | H27: =IF(G27>0,G27/F27-1,0) -> 0
F28: =IFERROR(VLOOKUP(E28,$C$11:$F$16,2,FALSE)*(1-$I$11),0) -> 0 | G28: =IFERROR(VLOOKUP(E28,$C$11:$G$16,5,FALSE)*(1-$H$11),0) -> 0 | H28: =IF(G28>0,G28/F28-1,0) -> 0
F29: =IFERROR(VLOOKUP(E29,$C$11:$F$16,2,FALSE)*(1-$I$11),0) -> 0 | G29: =IFERROR(VLOOKUP(E29,$C$11:$G$16,5,FALSE)*(1-$H$11),0) -> 0 | H29: =IF(G29>0,G29/F29-1,0) -> 0
F30: =IFERROR(VLOOKUP(E30,$C$11:$F$16,2,FALSE)*(1-$I$11),0) -> 0 | G30: =IFERROR(VLOOKUP(E30,$C$11:$G$16,5,FALSE)*(1-$H$11),0) -> 0 | H30: =IF(G30>0,G30/F30-1,0) -> 0
F31: =IFERROR(VLOOKUP(E31,$C$11:$F$16,2,FALSE)*(1-$I$11),0) -> 0 | G31: =IFERROR(VLOOKUP(E31,$C$11:$G$16,5,FALSE)*(1-$H$11),0) -> 0 | H31: =IF(G31>0,G31/F31-1,0) -> 0
F32: =IFERROR(VLOOKUP(E32,$C$11:$F$16,2,FALSE)*(1-$I$11),0) -> 0 | G32: =IFERROR(VLOOKUP(E32,$C$11:$G$16,5,FALSE)*(1-$H$11),0) -> 0 | H32: =IF(G32>0,G32/F32-1,0) -> 0
F33: =IFERROR(VLOOKUP(E33,$C$11:$F$16,2,FALSE)*(1-$I$11),0) -> 0 | G33: =IFERROR(VLOOKUP(E33,$C$11:$G$16,5,FALSE)*(1-$H$11),0) -> 0 | H33: =IF(G33>0,G33/F33-1,0) -> 0
C35: 1.3 Команда, субподряд
B36: Подразделение (ЦК/ЦФО/МВЗ) | C36: Компания/ФИО/Роль | D36: Ставка для компании ч/д, руб. | E36: Ставка для клиента ч/д, руб. | F36: Наценка (%)
F37: =IF(ISNUMBER(E37),E37/D37-1,"")
F38: =IF(ISNUMBER(E38),E38/D38-1,"")
F39: =IF(ISNUMBER(E39),E39/D39-1,"")
F40: =IF(ISNUMBER(E40),E40/D40-1,"")
C42: 1.4 Команда, группа компаний
B43: Подразделение (ЦК/ЦФО/МВЗ) | C43: Компания/ФИО/Роль | D43: Ставка для компании ч/д, руб. | E43: Ставка для клиента ч/д, руб. | F43: Наценка (%)
F44: =IF(ISNUMBER(E44),E44/D44-1,"")
F45: =IF(ISNUMBER(E45),E45/D45-1,"")
F46: =IF(ISNUMBER(E46),E46/D46-1,"")
...

Sheet Калькулятор бюджета по этапам
B1: 2. Финансовые показатели проекта по этапам
B3: Коэффициент | M3: с НДС
B4: 0 | M4: =M12*1.2 -> 0
B6: ОПУ | E6: Этапы проекта | M6: Итого
E7: Э1 | F7: Э2
B8: Трудозатраты, ч/д | E8: =SUM(E9:E11) -> 0 | F8: =SUM(F9:F11) -> 0 | G8: =SUM(G9:G11) -> 0 | H8: =SUM(H9:H11) -> 0 | I8: =SUM(I9:I11) -> 0 | J8: =SUM(J9:J11) -> 0 | K8: =SUM(K9:K11) -> 0 | L8: =SUM(L9:L11) -> 0 | M8: =SUM(E8:L8) -> 0
B9: Собственные | E9: =IFERROR(SUMIF(p_dt_c_ph,E$7,p_dt_c_eff),0) -> 0 | F9: =IFERROR(SUMIF(p_dt_c_ph,F$7,p_dt_c_eff),0) -> 0 | G9: =IFERROR(SUMIF(p_dt_c_ph,G$7,p_dt_c_eff),0) -> 0 | H9: =IFERROR(SUMIF(p_dt_c_ph,H$7,p_dt_c_eff),0) -> 0 | I9: =IFERROR(SUMIF(p_dt_c_ph,I$7,p_dt_c_eff),0) -> 0 | J9: =IFERROR(SUMIF(p_dt_c_ph,J$7,p_dt_c_eff),0) -> 0 | K9: =IFERROR(SUMIF(p_dt_c_ph,K$7,p_dt_c_eff),0) -> 0 | L9: =IFERROR(SUMIF(p_dt_c_ph,L$7,p_dt_c_eff),0) -> 0 | M9: =SUM(E9:L9) -> 0
B10: Субподряд | E10: =IFERROR(SUMIF(p_3p_c_ph,E$7,p_3p_c_eff),0) -> 0 | F10: =IFERROR(SUMIF(p_3p_c_ph,F$7,p_3p_c_eff),0) -> 0 | G10: =IFERROR(SUMIF(p_3p_c_ph,G$7,p_3p_c_eff),0) -> 0 | H10: =IFERROR(SUMIF(p_3p_c_ph,H$7,p_3p_c_eff),0) -> 0 | I10: =IFERROR(SUMIF(p_3p_c_ph,I$7,p_3p_c_eff),0) -> 0 | J10: =IFERROR(SUMIF(p_3p_c_ph,J$7,p_3p_c_eff),0) -> 0 | K10: =IFERROR(SUMIF(p_3p_c_ph,K$7,p_3p_c_eff),0) -> 0 | L10: =IFERROR(SUMIF(p_3p_c_ph,L$7,p_3p_c_eff),0) -> 0 | M10: =SUM(E10:L10) -> 0
B11: Группа компаний | E11: =IFERROR(SUMIF(p_ic_c_ph,E$7,p_ic_c_eff),0) -> 0 | F11: =IFERROR(SUMIF(p_ic_c_ph,F$7,p_ic_c_eff),0) -> 0 | G11: =IFERROR(SUMIF(p_ic_c_ph,G$7,p_ic_c_eff),0) -> 0 | H11: =IFERROR(SUMIF(p_ic_c_ph,H$7,p_ic_c_eff),0) -> 0 | I11: =IFERROR(SUMIF(p_ic_c_ph,I$7,p_ic_c_eff),0) -> 0 | J11: =IFERROR(SUMIF(p_ic_c_ph,J$7,p_ic_c_eff),0) -> 0 | K11: =IFERROR(SUMIF(p_ic_c_ph,K$7,p_ic_c_eff),0) -> 0 | L11: =IFERROR(SUMIF(p_ic_c_ph,L$7,p_ic_c_eff),0) -> 0 | M11: =SUM(E11:L11) -> 0
B12: Выручка | E12: =SUM(E13:E15) -> 0 | F12: =SUM(F13:F15) -> 0 | G12: =SUM(G13:G15) -> 0 | H12: =SUM(H13:H15) -> 0 | I12: =SUM(I13:I15) -> 0 | J12: =SUM(J13:J15) -> 0 | K12: =SUM(K13:K15) -> 0 | L12: =SUM(L13:L15) -> 0 | M12: =SUM(E12:L12) -> 0 | O12: Риски | P12: 0.1
B13: Собственная | E13: =IFERROR(SUMIF(p_dt_c_ph,E$7,p_dt_c_r),0)+IFERROR(SUMIF(p_dt_o_ph,E$7,p_dt_o_r),0)+IFERROR(SUMIF(p_dt_t_ph,E$7,p_dt_t_r),0) -> 0 | F13: =IFERROR(SUMIF(p_dt_c_ph,F$7,p_dt_c_r),0)+IFERROR(SUMIF(p_dt_o_ph,F$7,p_dt_o_r),0)+IFERROR(SUMIF(p_dt_t_ph,F$7,p_dt_t_r),0) -> 0 | G13: =IFERROR(SUMIF(p_dt_c_ph,G$7,p_dt_c_r),0)+IFERROR(SUMIF(p_dt_o_ph,G$7,p_dt_o_r),0)+IFERROR(SUMIF(p_dt_t_ph,G$7,p_dt_t_r),0) -> 0 | H13: =IFERROR(SUMIF(p_dt_c_ph,H$7,p_dt_c_r),0)+IFERROR(SUMIF(p_dt_o_ph,H$7,p_dt_o_r),0)+IFERROR(SUMIF(p_dt_t_ph,H$7,p_dt_t_r),0) -> 0 | I13: =IFERROR(SUMIF(p_dt_c_ph,I$7,p_dt_c_r),0)+IFERROR(SUMIF(p_dt_o_ph,I$7,p_dt_o_r),0)+IFERROR(SUMIF(p_dt_t_ph,I$7,p_dt_t_r),0) -> 0 | J13: =IFERROR(SUMIF(p_dt_c_ph,J$7,p_dt_c_r),0)+IFERROR(SUMIF(p_dt_o_ph,J$7,p_dt_o_r),0)+IFERROR(SUMIF(p_dt_t_ph,J$7,p_dt_t_r),0) -> 0 | K13: =IFERROR(SUMIF(p_dt_c_ph,K$7,p_dt_c_r),0)+IFERROR(SUMIF(p_dt_o_ph,K$7,p_dt_o_r),0)+IFERROR(SUMIF(p_dt_t_ph,K$7,p_dt_t_r),0) -> 0 | L13: =IFERROR(SUMIF(p_dt_c_ph,L$7,p_dt_c_r),0)+IFERROR(SUMIF(p_dt_o_ph,L$7,p_dt_o_r),0)+IFERROR(SUMIF(p_dt_t_ph,L$7,p_dt_t_r),0) -> 0 | M13: =SUM(E13:L13) -> 0 | O13: ГарантПод | P13: 0.1
B14: Субподряд | E14: =IFERROR(SUMIF(p_3p_c_ph,E$7,p_3p_c_r),0)+IFERROR(SUMIF(p_3p_o_ph,E$7,p_3p_o_r),0)+IFERROR(SUMIF(p_3p_t_ph,E$7,p_3p_t_r),0) -> 0 | F14: =IFERROR(SUMIF(p_3p_c_ph,F$7,p_3p_c_r),0)+IFERROR(SUMIF(p_3p_o_ph,F$7,p_3p_o_r),0)+IFERROR(SUMIF(p_3p_t_ph,F$7,p_3p_t_r),0) -> 0 | G14: =IFERROR(SUMIF(p_3p_c_ph,G$7,p_3p_c_r),0)+IFERROR(SUMIF(p_3p_o_ph,G$7,p_3p_o_r),0)+IFERROR(SUMIF(p_3p_t_ph,G$7,p_3p_t_r),0) -> 0 | H14: =IFERROR(SUMIF(p_3p_c_ph,H$7,p_3p_c_r),0)+IFERROR(SUMIF(p_3p_o_ph,H$7,p_3p_o_r),0)+IFERROR(SUMIF(p_3p_t_ph,H$7,p_3p_t_r),0) -> 0 | I14: =IFERROR(SUMIF(p_3p_c_ph,I$7,p_3p_c_r),0)+IFERROR(SUMIF(p_3p_o_ph,I$7,p_3p_o_r),0)+IFERROR(SUMIF(p_3p_t_ph,I$7,p_3p_t_r),0) -> 0 | J14: =IFERROR(SUMIF(p_3p_c_ph,J$7,p_3p_c_r),0)+IFERROR(SUMIF(p_3p_o_ph,J$7,p_3p_o_r),0)+IFERROR(SUMIF(p_3p_t_ph,J$7,p_3p_t_r),0) -> 0 | K14: =IFERROR(SUMIF(p_3p_c_ph,K$7,p_3p_c_r),0)+IFERROR(SUMIF(p_3p_o_ph,K$7,p_3p_o_r),0)+IFERROR(SUMIF(p_3p_t_ph,K$7,p_3p_t_r),0) -> 0 | L14: =IFERROR(SUMIF(p_3p_c_ph,L$7,p_3p_c_r),0)+IFERROR(SUMIF(p_3p_o_ph,L$7,p_3p_o_r),0)+IFERROR(SUMIF(p_3p_t_ph,L$7,p_3p_t_r),0) -> 0 | M14: =SUM(E14:L14) -> 0 | O14: РП | P14: 0.1
B15: Группа компаний | E15: =IFERROR(SUMIF(p_ic_c_ph,E$7,p_ic_c_r),0)+IFERROR(SUMIF(p_ic_o_ph,E$7,p_ic_o_r),0)+IFERROR(SUMIF(p_ic_t_ph,E$7,p_ic_t_r),0) -> 0 | F15: =IFERROR(SUMIF(p_ic_c_ph,F$7,p_ic_c_r),0)+IFERROR(SUMIF(p_ic_o_ph,F$7,p_ic_o_r),0)+IFERROR(SUMIF(p_ic_t_ph,F$7,p_ic_t_r),0) -> 0 | G15: =IFERROR(SUMIF(p_ic_c_ph,G$7,p_ic_c_r),0)+IFERROR(SUMIF(p_ic_o_ph,G$7,p_ic_o_r),0)+IFERROR(SUMIF(p_ic_t_ph,G$7,p_ic_t_r),0) -> 0 | H15: =IFERROR(SUMIF(p_ic_c_ph,H$7,p_ic_c_r),0)+IFERROR(SUMIF(p_ic_o_ph,H$7,p_ic_o_r),0)+IFERROR(SUMIF(p_ic_t_ph,H$7,p_ic_t_r),0) -> 0 | I15: =IFERROR(SUMIF(p_ic_c_ph,I$7,p_ic_c_r),0)+IFERROR(SUMIF(p_ic_o_ph,I$7,p_ic_o_r),0)+IFERROR(SUMIF(p_ic_t_ph,I$7,p_ic_t_r),0) -> 0 | J15: =IFERROR(SUMIF(p_ic_c_ph,J$7,p_ic_c_r),0)+IFERROR(SUMIF(p_ic_o_ph,J$7,p_ic_o_r),0)+IFERROR(SUMIF(p_ic_t_ph,J$7,p_ic_t_r),0) -> 0 | K15: =IFERROR(SUMIF(p_ic_c_ph,K$7,p_ic_c_r),0)+IFERROR(SUMIF(p_ic_o_ph,K$7,p_ic_o_r),0)+IFERROR(SUMIF(p_ic_t_ph,K$7,p_ic_t_r),0) -> 0 | L15: =IFERROR(SUMIF(p_ic_c_ph,L$7,p_ic_c_r),0)+IFERROR(SUMIF(p_ic_o_ph,L$7,p_ic_o_r),0)+IFERROR(SUMIF(p_ic_t_ph,L$7,p_ic_t_r),0) -> 0 | M15: =SUM(E15:L15) -> 0
B16: Расходы | E16: =E17+E21+E25 -> 0 | F16: =F17+F21+F25 -> 0 | G16: =G17+G21+G25 -> 0 | H16: =H17+H21+H25 -> 0 | I16: =I17+I21+I25 -> 0 | J16: =J17+J21+J25 -> 0 | K16: =K17+K21+K25 -> 0 | L16: =L17+L21+L25 -> 0 | M16: =SUM(E16:L16) -> 0
B17: Компания | E17: =SUM(E18:E20) -> 0 | F17: =SUM(F18:F20) -> 0 | G17: =SUM(G18:G20) -> 0 | H17: =SUM(H18:H20) -> 0 | I17: =SUM(I18:I20) -> 0 | J17: =SUM(J18:J20) -> 0 | K17: =SUM(K18:K20) -> 0 | L17: =SUM(L18:L20) -> 0 | M17: =SUM(E17:L17) -> 0 | O17: Формула для надбавки Рисков, ГарПод и РП
B18: Работы | E18: =IFERROR(SUMIF(p_dt_c_ph,E$7,p_dt_c_c),0) -> 0 | F18: =IFERROR(SUMIF(p_dt_c_ph,F$7,p_dt_c_c),0) -> 0 | G18: =IFERROR(SUMIF(p_dt_c_ph,G$7,p_dt_c_c),0) -> 0 | H18: =IFERROR(SUMIF(p_dt_c_ph,H$7,p_dt_c_c),0) -> 0 | I18: =IFERROR(SUMIF(p_dt_c_ph,I$7,p_dt_c_c),0) -> 0 | J18: =IFERROR(SUMIF(p_dt_c_ph,J$7,p_dt_c_c),0) -> 0 | K18: =IFERROR(SUMIF(p_dt_c_ph,K$7,p_dt_c_c),0) -> 0 | L18: =IFERROR(SUMIF(p_dt_c_ph,L$7,p_dt_c_c),0) -> 0 | M18: =SUM(E18:L18) -> 0 | O18: =СУММЕСЛИ(Диапазон всех ролей и трудозатрат;Роль;Диапазаон всех трудозатрат)*коэф-нт
B19: Прочие | E19: =IFERROR(SUMIF(p_dt_o_ph,E$7,p_dt_o_c),0) -> 0 | F19: =IFERROR(SUMIF(p_dt_o_ph,F$7,p_dt_o_c),0) -> 0 | G19: =IFERROR(SUMIF(p_dt_o_ph,G$7,p_dt_o_c),0) -> 0 | H19: =IFERROR(SUMIF(p_dt_o_ph,H$7,p_dt_o_c),0) -> 0 | I19: =IFERROR(SUMIF(p_dt_o_ph,I$7,p_dt_o_c),0) -> 0 | J19: =IFERROR(SUMIF(p_dt_o_ph,J$7,p_dt_o_c),0) -> 0 | K19: =IFERROR(SUMIF(p_dt_o_ph,K$7,p_dt_o_c),0) -> 0 | L19: =IFERROR(SUMIF(p_dt_o_ph,L$7,p_dt_o_c),0) -> 0 | M19: =SUM(E19:L19) -> 0
B20: Командировки | E20: =IFERROR(SUMIF(p_dt_t_ph,E$7,p_dt_t_c),0) -> 0 | F20: =IFERROR(SUMIF(p_dt_t_ph,F$7,p_dt_t_c),0) -> 0 | G20: =IFERROR(SUMIF(p_dt_t_ph,G$7,p_dt_t_c),0) -> 0 | H20: =IFERROR(SUMIF(p_dt_t_ph,H$7,p_dt_t_c),0) -> 0 | I20: =IFERROR(SUMIF(p_dt_t_ph,I$7,p_dt_t_c),0) -> 0 | J20: =IFERROR(SUMIF(p_dt_t_ph,J$7,p_dt_t_c),0) -> 0 | K20: =IFERROR(SUMIF(p_dt_t_ph,K$7,p_dt_t_c),0) -> 0 | L20: =IFERROR(SUMIF(p_dt_t_ph,L$7,p_dt_t_c),0) -> 0 | M20: =SUM(E20:L20) -> 0
B21: Субподряд | E21: =SUM(E22:E24) -> 0 | F21: =SUM(F22:F24) -> 0 | G21: =SUM(G22:G24) -> 0 | H21: =SUM(H22:H24) -> 0 | I21: =SUM(I22:I24) -> 0 | J21: =SUM(J22:J24) -> 0 | K21: =SUM(K22:K24) -> 0 | L21: =SUM(L22:L24) -> 0 | M21: =SUM(E21:L21) -> 0
B22: Работы | E22: =IFERROR(SUMIF(p_3p_c_ph,E$7,p_3p_c_c),0) -> 0 | F22: =IFERROR(SUMIF(p_3p_c_ph,F$7,p_3p_c_c),0) -> 0 | G22: =IFERROR(SUMIF(p_3p_c_ph,G$7,p_3p_c_c),0) -> 0 | H22: =IFERROR(SUMIF(p_3p_c_ph,H$7,p_3p_c_c),0) -> 0 | I22: =IFERROR(SUMIF(p_3p_c_ph,I$7,p_3p_c_c),0) -> 0 | J22: =IFERROR(SUMIF(p_3p_c_ph,J$7,p_3p_c_c),0) -> 0 | K22: =IFERROR(SUMIF(p_3p_c_ph,K$7,p_3p_c_c),0) -> 0 | L22: =IFERROR(SUMIF(p_3p_c_ph,L$7,p_3p_c_c),0) -> 0 | M22: =SUM(E22:L22) -> 0
B23: Прочие | E23: =IFERROR(SUMIF(p_3p_o_ph,E$7,p_3p_o_c),0) -> 0 | F23: =IFERROR(SUMIF(p_3p_o_ph,F$7,p_3p_o_c),0) -> 0 | G23: =IFERROR(SUMIF(p_3p_o_ph,G$7,p_3p_o_c),0) -> 0 | H23: =IFERROR(SUMIF(p_3p_o_ph,H$7,p_3p_o_c),0) -> 0 | I23: =IFERROR(SUMIF(p_3p_o_ph,I$7,p_3p_o_c),0) -> 0 | J23: =IFERROR(SUMIF(p_3p_o_ph,J$7,p_3p_o_c),0) -> 0 | K23: =IFERROR(SUMIF(p_3p_o_ph,K$7,p_3p_o_c),0) -> 0 | L23: =IFERROR(SUMIF(p_3p_o_ph,L$7,p_3p_o_c),0) -> 0 | M23: =SUM(E23:L23) -> 0
B24: Командировки | E24: =IFERROR(SUMIF(p_3p_t_ph,E$7,p_3p_t_c),0) -> 0 | F24: =IFERROR(SUMIF(p_3p_t_ph,F$7,p_3p_t_c),0) -> 0 | G24: =IFERROR(SUMIF(p_3p_t_ph,G$7,p_3p_t_c),0) -> 0 | H24: =IFERROR(SUMIF(p_3p_t_ph,H$7,p_3p_t_c),0) -> 0 | I24: =IFERROR(SUMIF(p_3p_t_ph,I$7,p_3p_t_c),0) -> 0 | J24: =IFERROR(SUMIF(p_3p_t_ph,J$7,p_3p_t_c),0) -> 0 | K24: =IFERROR(SUMIF(p_3p_t_ph,K$7,p_3p_t_c),0) -> 0 | L24: =IFERROR(SUMIF(p_3p_t_ph,L$7,p_3p_t_c),0) -> 0 | M24: =SUM(E24:L24) -> 0
B25: Группа Компаний | E25: =SUM(E26:E28) -> 0 | F25: =SUM(F26:F28) -> 0 | G25: =SUM(G26:G28) -> 0 | H25: =SUM(H26:H28) -> 0 | I25: =SUM(I26:I28) -> 0 | J25: =SUM(J26:J28) -> 0 | K25: =SUM(K26:K28) -> 0 | L25: =SUM(L26:L28) -> 0 | M25: =SUM(E25:L25) -> 0
B26: Работы | E26: =IFERROR(SUMIF(p_ic_c_ph,E$7,p_ic_c_c),0) -> 0 | F26: =IFERROR(SUMIF(p_ic_c_ph,F$7,p_ic_c_c),0) -> 0 | G26: =IFERROR(SUMIF(p_ic_c_ph,G$7,p_ic_c_c),0) -> 0 | H26: =IFERROR(SUMIF(p_ic_c_ph,H$7,p_ic_c_c),0) -> 0 | I26: =IFERROR(SUMIF(p_ic_c_ph,I$7,p_ic_c_c),0) -> 0 | J26: =IFERROR(SUMIF(p_ic_c_ph,J$7,p_ic_c_c),0) -> 0 | K26: =IFERROR(SUMIF(p_ic_c_ph,K$7,p_ic_c_c),0) -> 0 | L26: =IFERROR(SUMIF(p_ic_c_ph,L$7,p_ic_c_c),0) -> 0 | M26: =SUM(E26:L26) -> 0
B27: Прочие | E27: =IFERROR(SUMIF(p_ic_o_ph,E$7,p_ic_o_c),0) -> 0 | F27: =IFERROR(SUMIF(p_ic_o_ph,F$7,p_ic_o_c),0) -> 0 | G27: =IFERROR(SUMIF(p_ic_o_ph,G$7,p_ic_o_c),0) -> 0 | H27: =IFERROR(SUMIF(p_ic_o_ph,H$7,p_ic_o_c),0) -> 0 | I27: =IFERROR(SUMIF(p_ic_o_ph,I$7,p_ic_o_c),0) -> 0 | J27: =IFERROR(SUMIF(p_ic_o_ph,J$7,p_ic_o_c),0) -> 0 | K27: =IFERROR(SUMIF(p_ic_o_ph,K$7,p_ic_o_c),0) -> 0 | L27: =IFERROR(SUMIF(p_ic_o_ph,L$7,p_ic_o_c),0) -> 0 | M27: =SUM(E27:L27) -> 0
B28: Командировки | E28: =IFERROR(SUMIF(p_ic_t_ph,E$7,p_ic_t_c),0) -> 0 | F28: =IFERROR(SUMIF(p_ic_t_ph,F$7,p_ic_t_c),0) -> 0 | G28: =IFERROR(SUMIF(p_ic_t_ph,G$7,p_ic_t_c),0) -> 0 | H28: =IFERROR(SUMIF(p_ic_t_ph,H$7,p_ic_t_c),0) -> 0 | I28: =IFERROR(SUMIF(p_ic_t_ph,I$7,p_ic_t_c),0) -> 0 | J28: =IFERROR(SUMIF(p_ic_t_ph,J$7,p_ic_t_c),0) -> 0 | K28: =IFERROR(SUMIF(p_ic_t_ph,K$7,p_ic_t_c),0) -> 0 | L28: =IFERROR(SUMIF(p_ic_t_ph,L$7,p_ic_t_c),0) -> 0 | M28: =SUM(E28:L28) -> 0
B29: Прибыль | E29: =SUM(E30:E32) -> 0 | F29: =SUM(F30:F32) -> 0 | G29: =SUM(G30:G32) -> 0 | H29: =SUM(H30:H32) -> 0 | I29: =SUM(I30:I32) -> 0 | J29: =SUM(J30:J32) -> 0 | K29: =SUM(K30:K32) -> 0 | L29: =SUM(L30:L32) -> 0 | M29: =SUM(E29:L29) -> 0
B30: Собственная | E30: =E13-E17 -> 0 | F30: =F13-F17 -> 0 | G30: =G13-G17 -> 0 | H30: =H13-H17 -> 0 | I30: =I13-I17 -> 0 | J30: =J13-J17 -> 0 | K30: =K13-K17 -> 0 | L30: =L13-L17 -> 0 | M30: =SUM(E30:L30) -> 0
B31: Субподряд | E31: =E14-E21 -> 0 | F31: =F14-F21 -> 0 | G31: =G14-G21 -> 0 | H31: =H14-H21 -> 0 | I31: =I14-I21 -> 0 | J31: =J14-J21 -> 0 | K31: =K14-K21 -> 0 | L31: =L14-L21 -> 0 | M31: =SUM(E31:L31) -> 0
B32: Группа компаний | E32: =E15-E25 -> 0 | F32: =F15-F25 -> 0 | G32: =G15-G25 -> 0 | H32: =H15-H25 -> 0 | I32: =I15-I25 -> 0 | J32: =J15-J25 -> 0 | K32: =K15-K25 -> 0 | L32: =L15-L25 -> 0 | M32: =SUM(E32:L32) -> 0
B33: Прибыль (%) | E33: =IF(E12<>0,E29/E12,"") | F33: =IF(F12<>0,F29/F12,"") | G33: =IF(G12<>0,G29/G12,"") | H33: =IF(H12<>0,H29/H12,"") | I33: =IF(I12<>0,I29/I12,"") | J33: =IF(J12<>0,J29/J12,"") | K33: =IF(K12<>0,K29/K12,"") | L33: =IF(L12<>0,L29/L12,"") | M33: =IF(M12<>0,M29/M12,"")
B34: Собственная - % | E34: =IF(E13<>0,E30/E13,"") | F34: =IF(F13<>0,F30/F13,"") | G34: =IF(G13<>0,G30/G13,"") | H34: =IF(H13<>0,H30/H13,"") | I34: =IF(I13<>0,I30/I13,"") | J34: =IF(J13<>0,J30/J13,"") | K34: =IF(K13<>0,K30/K13,"") | L34: =IF(L13<>0,L30/L13,"") | M34: =IF(M13<>0,M30/M13,"")
B35: Субподряд - % | E35: =IF(E14<>0,E31/E14,"") | F35: =IF(F14<>0,F31/F14,"") | G35: =IF(G14<>0,G31/G14,"") | H35: =IF(H14<>0,H31/H14,"") | I35: =IF(I14<>0,I31/I14,"") | J35: =IF(J14<>0,J31/J14,"") | K35: =IF(K14<>0,K31/K14,"") | L35: =IF(L14<>0,L31/L14,"") | M35: =IF(M14<>0,M31/M14,"")
B36: Группа компаний - % | E36: =IF(E15<>0,E32/E15,"") | F36: =IF(F15<>0,F32/F15,"") | G36: =IF(G15<>0,G32/G15,"") | H36: =IF(H15<>0,H32/H15,"") | I36: =IF(I15<>0,I32/I15,"") | J36: =IF(J15<>0,J32/J15,"") | K36: =IF(K15<>0,K32/K15,"") | L36: =IF(L15<>0,L32/L15,"") | M36: =IF(M15<>0,M32/M15,"")
B38: 2.1-1 Калькулятор трудозатрат, собственные
B39: Этап | C39: Подразделение (ЦК/ЦФО/МВЗ) | D39: Описание работ | E39: ФИО | F39: Трудозатраты | G39: Коэффициент уверенности | H39: Резерв | I39: Общие трудозатраты | J39: Внутренняя стоимость | K39: Расходы | L39: Внешняя стоимость | M39: Подлежит оплате | N39: Выручка
F40: ч/д | G40: % | H40: ч/д | I40: ч/д | J40: ч/д, руб. | K40: руб. | L40: ч/д, руб. | M40: % | N40: руб.
B41: Э1 | H41: =(1-G41)*F41 -> 0 | I41: =F41+H41 -> 0 | J41: =IFERROR(VLOOKUP(E41,r_dt_team,4, FALSE),0) -> 0 | K41: =I41*J41 -> 0 | L41: =IFERROR(VLOOKUP(E41,r_dt_team,5, FALSE),0) -> 0 | N41: =I41*L41*(1+$B$4)*M41 -> 0
B42: Э1 | H42: =(1-G42)*F42 -> 0 | I42: =F42+H42 -> 0 | J42: =IFERROR(VLOOKUP(E42,r_dt_team,4, FALSE),0) -> 0 | K42: =I42*J42 -> 0 | L42: =IFERROR(VLOOKUP(E42,r_dt_team,5, FALSE),0) -> 0 | N42: =I42*L42*(1+$B$4)*M42 -> 0
B43: Э1 | H43: =(1-G43)*F43 -> 0 | I43: =F43+H43 -> 0 | J43: =IFERROR(VLOOKUP(E43,r_dt_team,4, FALSE),0) -> 0 | K43: =I43*J43 -> 0 | L43: =IFERROR(VLOOKUP(E43,r_dt_team,5, FALSE),0) -> 0 | N43: =I43*L43*(1+$B$4)*M43 -> 0
...

Sheet Опросник
B2: Кем заполняется | C2: № | D2: Тема вопроса | E2: Вопрос | F2: Ком | G2: Ответ
B3: Заполняется заказчиком | C3: 1 | D3: Определить заказчика и инвестора проекта | E3: Инвестор | F3: Например, в Банке А инвестор проекта совет председателей. Заказчик - Департамент Бухгалтерии. Пользователи системы – ключевые пользователи бухгалтерии разных департаментов учёта. Финансовая цель инвестора – сделать бухгалтерский учёт прозрачным, точным и получать оперативные показатели и отчёты в реальном времени.
C4: 2 | E4: Заказчик (Бенифициар)
C5: 3 | E5: Пользователи (Бизнес роль, аудитория):
C6: 4 | E6: Какие финансовые цели инвестора
C7: 5 | D7: Цель проекта | E7: Основная задача | F7: Например: Отслеживание и определение траектории движения посетителей внутри автосалона.
C8: 6 | E8: Постановка задачи | F8: Необходимо определить постановку задачи, какой ход выполнения проекта, какую работу необходимо провести. Например: трекинг посетителей от входа до выхода для гарантированно однократного учета каждого клиента.
C9: 7 | E9: Конечная цель | F9: Что является конечной целью Например: Ежедневный расчет количества уникальных посетителей в разрезе зон.
C10: 8 | E10: Критерии успешности проекта | F10: Понять конечную цель проекта, и что является критерием успешности выполнения проекта или метрики (какое численное изменение, имеющее смысл с бизнес-точки зрения, мы планируем получить), которые требуется добиться. Например: точность детекции людей на входе в автосалон - 98%, точность разделения людей на сотрудников и посетителей - 80%.
C11: 9 | D11: Сроки проекта | F11: Оценить реальные сроки с учётом сезонности, времени и праздничных дней. В период закрытия или в конце года нежелательно проводить тестирование и ОПЭ. Также необходимо учитывать реальные ресурсы и возможности исполнителя. Иногда, физически невозможно реализовать проект в указанный срок и его нужно переносить.
B12: Заполняется совместно с Заказчиком и Исполнителем | D12: Анализ исходных данных | E12: Определить, какие и чьи это будут мощности | F12: В разрезе сред разработки, тестирования, продуктива. Облако (Вид подписки: прерываемая, непрерываемая) или ОнПремайс (Ответственность по предоставлению доступа к ресурсам лежит на исполнителе).
E13: Требуется ли дозакупить оборудование | F13: Достаточно ли мощностей, если "нет" до необходимо докупить.
E14: Дополнительно оборудование | F14: Оборудование, которые может понадобиться для осуществления проекта. Например: камера, датчики, сенсоры.
D15: Драйверы | F15: Для каждого проекта, продукта, услуги свои драйверы, которые влияют на трудозатраты.
B18: Для ИИ
B19: Заполняется совместно с Заказчиком и Исполнителем | C19: 10 | D19: Анализ исходных данных | E19: Объём и характеристики исходных данных. | F19: Оценить объём исходных данных и их характеристики. Например: табличне данные, неструктурированных данных, структуры данных, типы переменных и формат. Количество и сложность данных, необходимых для обучения и поддержки моделей ИИ, существенно влияет на стоимость проекта.
C20: 11 | E20: Качество достаточности и валидации данных | F20: (Опционально) Наличие ошибок, пропусков, дубликатов, аномалий или несоответствий. Если данные требуют очистки, нормализации или других процессов, это может повлиять на трудоемкость проекта. Если у нас исходных данных нет или они плохие, а мы собираемся строить на них модель ML, то от проекта лучше отказаться или необходимо привлекать субподрядчиков. Возможно покупка и поиск дополнительных данных.
C21: 12 | E21: Возможность купить дополнительные или использовать публичные данные | F21: (Опционально)
C22: 13 | E22: Провести анализ исходных данных на предмет их качества разметки | F22: Процесс добавления тэгов в сырые данные, с целью показать моделе машинного обучения целевые атрибуты (ответы), которые она должна предсказывать.
C23: 14 | D23: Драйверы | E23: Количество предполагаемых моделей | F23: (Опционально) Количество, тип и сложность модели.
C24: 15 | E24: Источники данных | F24: Источники данных, их количество в инфраструктуре и способы их сбора
C25: 16 | E25: Бизнес-домены. | F25: Какие бизнес области входят в рамки проекта (закупки, финансы, производство, и тп)
C26: 17 | E26: WorkFlow | F26: Количество WorkFlow процессов
B27: Заполняется Исполнителем | C27: 18 | D27: Техническая инфраструктура проекта | E27: Технические характеристики и стеки технологий | F27: если есть предпочтения и варианты предложений. В каких контурах осуществляется разработка, тестирование и пром использование.
C28: 19 | E28: Определить, какие это будут мощности | F28: В разрезе сред разработки, тестирования, продуктива. Облако (Вид подписки: прерываемая, непрерываемая) или ОнПремайс (Ответственность по предоставлению доступа к ресурсам лежит на исполнителе).
C29: 20 | E29: Технические характеристики системы для машинного обучения | F29: В разрезе сред разработки, тестирования, продуктива. Указать по порядку: CPU, GPU, RAM, SSD. Видеокарты по возрастанию мощности: Tesla V100, A100, H100 Средние характеристики: CPU - 64 Core, GPU – 2* A100, RAM - 128 Gb, SSD - 2 Tb.
C30: 21 | E30: Среда объектного хранилища | F30: Например, S3 (от Amazon), S3 Like, Google Cloud.
C31: 22 | E31: Набор инструментов для управления моделями машинного обучения | F31: Mlops инструменты. Например: ClearML
C32: 23 | E32: Платформа для размети/управления данными для машинного обучения | F32: Например: Label Studio
C33: 24 | E33: Система для управления версионностью | F33: Например: GIT и его аналоги. Принадлежит MS, возможно привлечение своих аналогов/репозитариев.
C34: 25 | E34: Среда разработки | F34: Например: JupyterHub/JupyterLab или заказчик сам предоставляет среду.
C35: 26 | E35: Провести анализ исходных данных на предмет их качества разметки | F35: Процесс добавления тэгов в сырые данные, чтобы показать моделе машинного обучения целевые атрибуты (ответы), которые она должна предсказывать.
C36: 27 | E36: Типы моделей и алгоритмы | F36: (если применимо на данном этапе). Использование сложных алгоритмов и моделей, таких как нейронные сети глубокого обучения, может требовать более высоких затрат на обучение и интеграцию.
C37: 28 | E37: Выбор фреймворков | F37: (если применимо на данном этапе) Например: PyTorch, TensorFlow
C38: 29 | E38: Дополнительно оборудование | F38: Оборудование, которые может понадобиться для осуществления проекта. Например: камера, датчики, сенсоры.

Sheet Проектные ограничения
A1: № | B1: Пункт требований | C1: Ограничения

Sheet Калькулятор
B2: Статья затрат | D2: Параметры | E2: Расходы | F2: Прибыль | G2: Стоимость Без НДС | H2: Стоимость С НДС | I2: Маржа | J2: Комментарий
B3: aCRM | C3: Внедрение | D3: Пакетный маркетинг | E3: 20463080 | F3: =G3-E3 -> 8653568 | G3: 29116648 | H3: =G3*1.2 -> 34939978 | I3: =SUM(F3:F4)/SUM(G3:G4) -> 0.29720344 | J3: Количество кампаний: 10 кампаний Количество пользователей: более 50 млн Средний размер сегментов: в зависимости от информационного канала от 50 тыс. до 2 млн редний размер контрольной группы: в зависимости от информационного канала.
C4: Лицензия | D4: Пакетный маркетинг. Клиентская база анлим | E4: 0 | F4: =G4-E4 -> 0 | H4: =G4 -> 0
B6: Kore.DWH | C6: Внедрение | D6: Инсталляция и внедрение | E6: 333600 | F6: =G6-E6 -> 135600 | G6: 469200 | H6: =G6*1.2 -> 563040 | I6: =F6/G6 -> 0.28900256 | J6: Риски и ГП не заложены
C7: Лицензия | D7: бессрочная лицензия на базовый пакет | F7: =G7-E7 -> 5000000 | G7: 5000000 | H7: =G7 -> 5000000 | I7: =F7/G7 -> 1 | J7: Лицензируется по провайдерам ресурсов Лицензии: 5 млн – бессрочная лицензия на базовый пакет
B9: Нормализатор | C9: Внедрение | D9: Инсталляция и внедрение | E9: 667200 | F9: =G9-E9 -> 271200 | G9: 938400 | H9: =G9*1.2 -> 1126080 | I9: =F9/G9 -> 0.28900256 | J9: Риски и ГП не заложены
C10: Лицензия | D10: бессрочная лицензия на базовый пакет | F10: =G10-E10 -> 7000000 | G10: 7000000 | H10: =G10 -> 7000000 | I10: =F10/G10 -> 1 | J10: Лицензируется по количеству процедур Лицензии: 7 млн – бессрочная лицензия на базовый пакет
B12: BI | C12: Внедрение | E12: 8529440 | F12: =G12-E12 -> 3456560 | G12: 11986000 | H12: =G12*1.2 -> 14383200 | I12: =F12/G12 -> 0.28838311
C13: Лицензия | F13: =G13-E13 -> 0 | H13: =G13 -> 0 | I13: =F13/G13 -> #DIV/0!
B15: PIX BI | C15: Лицензия | D15: 5 Пользователи PRO 25 Пользователи BASE | E15: =3062500*0.8 -> 2450000 | F15: =G15-E15 -> 612500 | G15: 3062500 | H15: =G15 -> 3062500 | I15: =(G15-E15)/G15 -> 0.2
C16: Поддержка | D16: 1 год | E16: 551250 | F16: =G16-E16 -> 0 | G16: 551250 | H16: =G16*1.2 -> 661500 | I16: =(G16-E16)/G16 -> 0
B19: Итого | E19: =SUM(E3:E17) -> 32994570 | F19: =SUM(F3:F17) -> 25129428 | G19: =SUM(G3:G17) -> 58123998 | H19: =SUM(H3:H17) -> 66736298 | I19: =F19/G19 -> 0.4323417
B20: без учета инфраструктуры и технической поддержки
B21: Включает в себя работы по проекту, лицензию на 1 год и гарантийную поддержку на 1 год.
C23: Вставить в презентацию или удалить
C24: Поля для редактирования

Sheet План
B2: CV + интеграция
B3: Этап | C3: Наименование работы \ Месяц | D3: Длительность недель | E3: М1 | I3: М2 | M3: М3 | Q3: М4 | U3: М5 | Y3: М6 | AC3: М7 | AG3: М8 | AK3: М9 | AO3: М10 | AS3: М11
B4: 1 | C4: Инфраструктура | D4: 13
B5: 2 | C5: CV | D5: 3
B6: 3 | C6: Интеграция (UI) | D6: 4
B7: 4 | C7: Завершение проекта | D7: 5
B8: 5 | D8: 7
C9: ИТОГО: | D9: =SUM(D4:D8) -> 32
B12: CV + интеграция
B13: Этап | C13: Наименование работы \ Месяц | D13: Длительность недель | E13: М1 | I13: М2 | M13: М3
B14: 1 | C14: Анализ, проектирование | D14: 4
B15: 2 | C15: Разработка и тестирование интеграции | D15: 4
B16: 3 | C16: Разработка и тестирование CV | D16: 10
B17: 4 | C17: ПСИ | D17: 2
C18: Общая длительность: | D18: =SUM(D14:D17) -> 20
B21: aCRM. БАТЧ + BI
B22: Этап | C22: Наименование работы \ Месяц | D22: Длительность недель | E22: М1 | I22: М2 | M22: М3 | Q22: М4 | U22: М5 | Y22: М6 | AC22: М7 | AG22: М8 | AK22: М9 | AO22: М10 | AS22: М11 | AW22: М12
B23: 1 | C23: Анализ aCRM | D23: 13
B24: 2 | C24: Внедрение Kore.DWH | D24: 3
B25: 3 | C25: Внедрение Нормализатора | D25: 4
B26: 4 | C26: Анализ BI | D26: 5
B27: 5 | C27: Проектирование BI | D27: 7
B28: 6 | C28: Внедрение BI | D28: 7
B29: 7 | C29: Ввод в эксплуатацию BI | D29: 16
B30: 8 | C30: Проектирование aCRM | D30: 7
B31: 9 | C31: Внедрение aCRM | D31: 7
B32: 10 | C32: Ввод в эксплуатацию aCRM | D32: 16
C33: ИТОГО: | D33: =SUM(D23:D32) -> 85
B35: BI график проекта
B36: Этап | C36: Наименование работы \ Месяц | D36: Длительность недель | E36: М1 | I36: М2 | M36: М3 | Q36: М4 | U36: М5 | Y36: М6 | AC36: М7 | AG36: М8 | AK36: М9 | AO36: М10 | AS36: М11
B37: 1 | C37: Анализ BI | D37: 5
B38: 2 | C38: Проектирование BI | D38: 7
B39: 3 | C39: Внедрение BI | D39: 7
B40: 4 | C40: Ввод в эксплуатацию BI | D40: 16
C41: ИТОГО: | D41: =D37+D38+D39+D40 -> 35

Sheet Смета проекта
B2: № | C2: Наименование работы | D2: Результат | E2: Итого, ЧД | G2: Аналитик | H2: Аналитик | I2: Ведуший разработчик | J2: Разработчик | K2: Разработчик | L2: Разработчик | M2: Администратор СУБД | N2: Инженер DevOps | O2: Архитектор решения | P2: PM | Q2: Длительность , недель | R2: Длительность , недель | S2: M1 | W2: M2 | AA2: M3 | AE2: M4 | AI2: M5 | AM2: M6 | AQ2: M7 | AU2: M8 | AY2: M9 | BC2: M10 | BG2: M11 | BK2: M12
C3: Команда
E4: Ставка внешняя | S4: 1 | T4: 2 | U4: 3 | V4: 4 | W4: 5 | X4: 6 | Y4: 7 | Z4: 8 | AA4: 9 | AB4: 10 | AC4: 11 | AD4: 12 | AE4: 13 | AF4: 14 | AG4: 15 | AH4: 16 | AI4: 13 | AJ4: 14 | AK4: 15 | AL4: 16 | AM4: 13 | AN4: 14 | AO4: 15 | AP4: 16 | AQ4: 13 | AR4: 14 | AS4: 15 | AT4: 16 | AU4: 13 | AV4: 14 | AW4: 15 | AX4: 16 | AY4: 13 | AZ4: 14 | BA4: 15 | BB4: 16 | BC4: 13 | BD4: 13 | BE4: 13 | BF4: 13 | BG4: 13 | BH4: 13 | BI4: 13 | BJ4: 13 | BK4: 13 | BL4: 13 | BM4: 13 | BN4: 13
E5: Процент увеличения | F5: 10 | G5: =G4*($F$5/100+1) -> 0 | H5: =H4*($F$5/100+1) -> 0 | I5: =I4*($F$5/100+1) -> 0 | J5: =J4*($F$5/100+1) -> 0 | K5: =K4*($F$5/100+1) -> 0 | L5: =L4*($F$5/100+1) -> 0 | M5: =M4*($F$5/100+1) -> 0 | N5: =N4*($F$5/100+1) -> 0 | ... P5: =P4*($F$5/100+1) -> 0 | S5: 1 | T5: 2 | U5: 3 | V5: 4 | W5: 5 | X5: 6 | Y5: 7 | Z5: 8 | AA5: 9 | AB5: 10 | AC5: 11 | AD5: 12 | AE5: 13 | AF5: 14 | AG5: 15 | AH5: 16 | AI5: 13 | AJ5: 14 | AK5: 15 | AL5: 16 | AM5: 13 | AN5: 14 | AO5: 15 | AP5: 16 | AQ5: 13 | AR5: 14 | AS5: 15 | AT5: 16 | AU5: 13 | AV5: 14 | AW5: 15 | AX5: 16 | AY5: 13 | AZ5: 14 | BA5: 15 | BB5: 16 | BC5: 13 | BD5: 14 | BE5: 15 | BF5: 16 | BG5: 13 | BH5: 14 | BI5: 15 | BJ5: 16 | BK5: 13 | BL5: 14 | BM5: 15 | BN5: 16
E6: ч.д. | F6: Стоимость, руб без НДС | G6: ч.д. | H6: ч.д. | I6: ч.д. | J6: ч.д. | K6: ч.д. | L6: ч.д. | M6: ч.д. | N6: ч.д. | O6: ч.д. | P6: ч.д.
C7: Итого выручка | E7: =E8 -> 0 | F7: =F8 -> 0 | G7: =G5*G8 -> 0 | H7: =H5*H8 -> 0 | I7: =I5*I8 -> 0 | J7: =J5*J8 -> 0 | K7: =K5*K8 -> 0 | L7: =L5*L8 -> 0 | M7: =M5*M8 -> 0 | N7: =N5*N8 -> 0 | ... P7: =P5*P8 -> 0
C8: Итого чд | E8: =SUM(E9:E38)/2 -> 0 | F8: =SUM(F9:F38)/2 -> 0 | G8: =SUM(G9:G38)/2 -> 0 | H8: =SUM(H9:H38)/2 -> 0 | I8: =SUM(I9:I38)/2 -> 0 | J8: =SUM(J9:J38)/2 -> 0 | K8: =SUM(K9:K38)/2 -> 0 | L8: =SUM(L9:L38)/2 -> 0 | ... P8: =SUM(P9:P38)/2 -> 0 | Q8: =SUM(S8:BJ8) -> 44 | R8: =SUM(S8:BJ8) -> 44 | S8: 1 | T8: 1 | U8: 1 | V8: 1 | W8: 1 | X8: 1 | Y8: 1 | Z8: 1 | AA8: 1 | AB8: 1 | AC8: 1 | AD8: 1 | AE8: 1 | AF8: 1 | AG8: 1 | AH8: 1 | AI8: 1 | AJ8: 1 | AK8: 1 | AL8: 1 | AM8: 1 | AN8: 1 | AO8: 1 | AP8: 1 | AQ8: 1 | AR8: 1 | AS8: 1 | AT8: 1 | AU8: 1 | AV8: 1 | AW8: 1 | AX8: 1 | AY8: 1 | AZ8: 1 | BA8: 1 | BB8: 1 | BC8: 1 | BD8: 1 | BE8: 1 | BF8: 1 | BG8: 1 | BH8: 1 | BI8: 1 | BJ8: 1 | BK8: 1 | BL8: 1 | BM8: 1 | BN8: 1
B9: 1 | C9: Разработка вернеуровневой архитектуры и установка | E9: =SUM(E10:E15) -> 0 | F9: =SUM(F10:F15) -> 0 | G9: =SUM(G10:G15) -> 0 | H9: =SUM(H10:H15) -> 0 | I9: =SUM(I10:I15) -> 0 | J9: =SUM(J10:J15) -> 0 | K9: =SUM(K10:K15) -> 0 | L9: =SUM(L10:L15) -> 0 | ... P9: =SUM(P10:P15) -> 0 | Q9: =MAX(G9:P9)/5 -> 0 | R9: =MAX(G9:Q9)/5 -> 0 | S9: 1 | T9: 1 | U9: 1 | V9: 1 | W9: 1 | X9: 1 | Y9: 1 | Z9: 1 | AA9: 1
Q10: =MAX(G10:P10)/5 -> 0 | R10: =MAX(G10:Q10)/5 -> 0
Q11: =MAX(G11:P11)/5 -> 0 | R11: =MAX(G11:Q11)/5 -> 0
Q12: =MAX(G12:P12)/5 -> 0 | R12: =MAX(G12:Q12)/5 -> 0
Q13: =MAX(G13:P13)/5 -> 0 | R13: =MAX(G13:Q13)/5 -> 0
Q14: =MAX(G14:P14)/5 -> 0 | R14: =MAX(G14:Q14)/5 -> 0
Q15: =MAX(G15:P15)/5 -> 0 | R15: =MAX(G15:Q15)/5 -> 0
B16: 2 | C16: Подготовка к миграции | E16: =SUM(E17:E20) -> 0 | F16: =SUM(F17:F20) -> 0 | G16: =SUM(G17:G20) -> 0 | H16: =SUM(H17:H20) -> 0 | I16: =SUM(I17:I20) -> 0 | J16: =SUM(J17:J20) -> 0 | K16: =SUM(K17:K20) -> 0 | L16: =SUM(L17:L20) -> 0 | ... P16: =SUM(P17:P20) -> 0 | Q16: =MAX(G16:P16)/5 -> 0 | R16: =MAX(G16:Q16)/5 -> 0 | X16: 1 | Y16: 1 | Z16: 1 | AA16: 1 | AB16: 1 | AC16: 1
Q17: =MAX(G17:P17)/5 -> 0 | R17: =MAX(G17:Q17)/5 -> 0
Q18: =MAX(G18:P18)/5 -> 0 | R18: =MAX(G18:Q18)/5 -> 0
Q19: =MAX(G19:P19)/5 -> 0 | R19: =MAX(G19:Q19)/5 -> 0
Q20: =MAX(G20:P20)/5 -> 0 | R20: =MAX(G20:Q20)/5 -> 0
B21: 3 | C21: Миграция | D21: =E21*0.4 -> 0 | E21: =SUM(E22:E29) -> 0 | F21: =SUM(F22:F29) -> 0 | G21: =SUM(G22:G29) -> 0 | H21: =SUM(H22:H29) -> 0 | I21: =SUM(I22:I29) -> 0 | J21: =SUM(J22:J29) -> 0 | K21: =SUM(K22:K29) -> 0 | L21: =SUM(L22:L29) -> 0 | ... P21: =SUM(P22:P29) -> 0 | Q21: =MAX(G21:P21)/5 -> 0 | R21: =MAX(G21:Q21)/5 -> 0 | AC21: 1 | AD21: 1 | AE21: 1 | AF21: 1 | AG21: 1 | AH21: 1 | AI21: 1 | AJ21: 1 | AK21: 1 | AL21: 1
Q22: =MAX(G22:P22)/5 -> 0 | R22: =MAX(G22:Q22)/5 -> 0
Q23: =MAX(G23:P23)/5 -> 0 | R23: =MAX(G23:Q23)/5 -> 0
Q24: =MAX(G24:P24)/5 -> 0 | R24: =MAX(G24:Q24)/5 -> 0
Q25: =MAX(G25:P25)/5 -> 0 | R25: =MAX(G25:Q25)/5 -> 0
Q26: =MAX(G26:P26)/5 -> 0 | R26: =MAX(G26:Q26)/5 -> 0
Q27: =MAX(G27:P27)/5 -> 0 | R27: =MAX(G27:Q27)/5 -> 0
Q28: =MAX(G28:P28)/5 -> 0 | R28: =MAX(G28:Q28)/5 -> 0
Q29: =MAX(G29:P29)/5 -> 0 | R29: =MAX(G29:Q29)/5 -> 0
B30: 4 | C30: Функциональное тестирование | E30: =SUM(E31:E34) -> 0 | F30: =SUM(F31:F34) -> 0 | G30: =SUM(G31:G34) -> 0 | H30: =SUM(H31:H34) -> 0 | I30: =SUM(I31:I34) -> 0 | J30: =SUM(J31:J34) -> 0 | K30: =SUM(K31:K34) -> 0 | L30: =SUM(L31:L34) -> 0 | ... P30: =SUM(P31:P34) -> 0 | Q30: =MAX(G30:P30)/5 -> 0 | R30: =MAX(G30:Q30)/5 -> 0 | AM30: 1 | AN30: 1 | AO30: 1
Q31: =MAX(G31:P31)/5 -> 0 | R31: =MAX(G31:Q31)/5 -> 0
Q32: =MAX(G32:P32)/5 -> 0 | R32: =MAX(G32:Q32)/5 -> 0
Q33: =MAX(G33:P33)/5 -> 0 | R33: =MAX(G33:Q33)/5 -> 0
Q34: =MAX(G34:P34)/5 -> 0 | R34: =MAX(G34:Q34)/5 -> 0
B35: 5 | C35: ПСИ | E35: =SUM(E36:E39) -> 0 | F35: =SUM(F36:F38) -> 0 | G35: =SUM(G36:G38) -> 0 | H35: =SUM(H36:H38) -> 0 | I35: =SUM(I36:I38) -> 0 | J35: =SUM(J36:J38) -> 0 | K35: =SUM(K36:K38) -> 0 | L35: =SUM(L36:L38) -> 0 | M35: =SUM(M36:M38) -> 0 | ... P35: =SUM(P36:P38) -> 0 | Q35: =MAX(G35:P35)/5 -> 0 | R35: =MAX(G35:Q35)/5 -> 0 | AP35: 1 | AQ35: 1 | AR35: 1
Q36: =MAX(G36:P36)/5 -> 0 | R36: =MAX(G36:Q36)/5 -> 0
Q37: =MAX(G37:P37)/5 -> 0 | R37: =MAX(G37:Q37)/5 -> 0
Q38: =MAX(G38:P38)/5 -> 0 | R38: =MAX(G38:Q38)/5 -> 0
Q39: =MAX(G39:P39)/5 -> 0 | R39: =MAX(G39:Q39)/5 -> 0

Sheet Планирование ресурсов
A1: Расходы/ Месяцы | C1: =DATEVALUE("01/01/"&YEAR(ОПУ!B1)) -> 1 | D1: =EDATE(C1,1) -> 32 | E1: =EDATE(D1,1) -> 61 | F1: =EDATE(E1,1) -> 92 | G1: =EDATE(F1,1) -> 122 | H1: =EDATE(G1,1) -> 153 | I1: =EDATE(H1,1) -> 183 | J1: =EDATE(I1,1) -> 214 | K1: =EDATE(J1,1) -> 245 | ... N1: =EDATE(M1,1) -> 336 | O1: Итого: | P1: По смете:
A2: Итого: | C2: =SUM(C3:C5) -> 0 | D2: =SUM(D3:D5) -> 0 | E2: =SUM(E3:E5) -> 0 | F2: =SUM(F3:F5) -> 0 | G2: =SUM(G3:G5) -> 0 | H2: =SUM(H3:H5) -> 0 | I2: =SUM(I3:I5) -> 0 | J2: =SUM(J3:J5) -> 0 | ... N2: =SUM(N3:N5) -> 0 | O2: =SUM(C2:N2) -> 0 | P2: ='Калькулятор бюджета по этапам'!M17 -> 0
A3: Работы | C3: =SUMPRODUCT($B$7:$B994,C7:C994) -> 0 | D3: =SUMPRODUCT($B$7:$B994,D7:D994) -> 0 | E3: =SUMPRODUCT($B$7:$B994,E7:E994) -> 0 | F3: =SUMPRODUCT($B$7:$B994,F7:F994) -> 0 | G3: =SUMPRODUCT($B$7:$B994,G7:G994) -> 0 | H3: =SUMPRODUCT($B$7:$B994,H7:H994) -> 0 | I3: =SUMPRODUCT($B$7:$B994,I7:I994) -> 0 | J3: =SUMPRODUCT($B$7:$B994,J7:J994) -> 0 | ... N3: =SUMPRODUCT($B$7:$B994,N7:N994) -> 0 | O3: =SUM(C3:N3) -> 0 | P3: ='Калькулятор бюджета по этапам'!M18 -> 0
A4: Прочие | O4: =SUM(C4:N4) -> 0 | P4: ='Калькулятор бюджета по этапам'!M19 -> 0
A5: Командировки | O5: =SUM(C5:N5) -> 0 | P5: ='Калькулятор бюджета по этапам'!M20 -> 0
A6: Команда | B6: Внутренняя ставка | C6: Трудозатраты, ч/д | O6: =SUM(O7:O1993) -> 0 | P6: =SUM(P7:P1993) -> 0
B7: =IFERROR(VLOOKUP(A7,r_dt_team,4, FALSE),0) -> 0 | C7: =P7-SUM(D7:J7) -> 0 | D7: =ROUND($P7/8,0) -> 0 | E7: =ROUND($P7/8,0) -> 0 | F7: =ROUND($P7/8,0) -> 0 | G7: =ROUND($P7/8,0) -> 0 | H7: =ROUND($P7/8,0) -> 0 | I7: =ROUND($P7/8,0) -> 0 | J7: =ROUND($P7/8,0) -> 0 | O7: =SUM(C7:N7) -> 0 | P7: =IFERROR(SUMIF(p_dt_c_person,A7,p_dt_c_eff),0) -> 0
B8: =IFERROR(VLOOKUP(A8,r_dt_team,4, FALSE),0) -> 0 | C8: =P8-SUM(D8:J8) -> 0 | D8: =ROUND($P8/8,0) -> 0 | E8: =ROUND($P8/8,0) -> 0 | F8: =ROUND($P8/8,0) -> 0 | G8: =ROUND($P8/8,0) -> 0 | H8: =ROUND($P8/8,0) -> 0 | I8: =ROUND($P8/8,0) -> 0 | J8: =ROUND($P8/8,0) -> 0 | O8: =SUM(C8:N8) -> 0 | P8: =IFERROR(SUMIF(p_dt_c_person,A8,p_dt_c_eff),0) -> 0
B9: =IFERROR(VLOOKUP(A9,r_dt_team,4, FALSE),0) -> 0 | C9: =P9-SUM(D9:J9) -> 0 | D9: =ROUND($P9/8,0) -> 0 | E9: =ROUND($P9/8,0) -> 0 | F9: =ROUND($P9/8,0) -> 0 | G9: =ROUND($P9/8,0) -> 0 | H9: =ROUND($P9/8,0) -> 0 | I9: =ROUND($P9/8,0) -> 0 | J9: =ROUND($P9/8,0) -> 0 | O9: =SUM(C9:N9) -> 0 | P9: =IFERROR(SUMIF(p_dt_c_person,A9,p_dt_c_eff),0) -> 0
B10: =IFERROR(VLOOKUP(A10,r_dt_team,4, FALSE),0) -> 0 | C10: =P10-SUM(D10:J10) -> 0 | D10: =ROUND($P10/8,0) -> 0 | E10: =ROUND($P10/8,0) -> 0 | F10: =ROUND($P10/8,0) -> 0 | G10: =ROUND($P10/8,0) -> 0 | H10: =ROUND($P10/8,0) -> 0 | I10: =ROUND($P10/8,0) -> 0 | J10: =ROUND($P10/8,0) -> 0 | O10: =SUM(C10:N10) -> 0 | P10: =IFERROR(SUMIF(p_dt_c_person,A10,p_dt_c_eff),0) -> 0
B11: =IFERROR(VLOOKUP(A11,r_dt_team,4, FALSE),0) -> 0 | C11: =P11-SUM(D11:J11) -> 0 | D11: =ROUND($P11/8,0) -> 0 | E11: =ROUND($P11/8,0) -> 0 | F11: =ROUND($P11/8,0) -> 0 | G11: =ROUND($P11/8,0) -> 0 | H11: =ROUND($P11/8,0) -> 0 | I11: =ROUND($P11/8,0) -> 0 | J11: =ROUND($P11/8,0) -> 0 | O11: =SUM(C11:N11) -> 0 | P11: =IFERROR(SUMIF(p_dt_c_person,A11,p_dt_c_eff),0) -> 0
B12: =IFERROR(VLOOKUP(A12,r_dt_team,4, FALSE),0) -> 0 | C12: =P12-SUM(D12:J12) -> 0 | D12: =ROUND($P12/8,0) -> 0 | E12: =ROUND($P12/8,0) -> 0 | F12: =ROUND($P12/8,0) -> 0 | G12: =ROUND($P12/8,0) -> 0 | H12: =ROUND($P12/8,0) -> 0 | I12: =ROUND($P12/8,0) -> 0 | J12: =ROUND($P12/8,0) -> 0 | O12: =SUM(C12:N12) -> 0 | P12: =IFERROR(SUMIF(p_dt_c_person,A12,p_dt_c_eff),0) -> 0
B13: =IFERROR(VLOOKUP(A13,r_dt_team,4, FALSE),0) -> 0 | C13: =P13-SUM(D13:J13) -> 0 | D13: =ROUND($P13/8,0) -> 0 | E13: =ROUND($P13/8,0) -> 0 | F13: =ROUND($P13/8,0) -> 0 | G13: =ROUND($P13/8,0) -> 0 | H13: =ROUND($P13/8,0) -> 0 | I13: =ROUND($P13/8,0) -> 0 | J13: =ROUND($P13/8,0) -> 0 | O13: =SUM(C13:N13) -> 0 | P13: =IFERROR(SUMIF(p_dt_c_person,A13,p_dt_c_eff),0) -> 0
B14: =IFERROR(VLOOKUP(A14,r_dt_team,4, FALSE),0) -> 0 | C14: =P14-SUM(D14:J14) -> 0 | D14: =ROUND($P14/8,0) -> 0 | E14: =ROUND($P14/8,0) -> 0 | F14: =ROUND($P14/8,0) -> 0 | G14: =ROUND($P14/8,0) -> 0 | H14: =ROUND($P14/8,0) -> 0 | I14: =ROUND($P14/8,0) -> 0 | J14: =ROUND($P14/8,0) -> 0 | O14: =SUM(C14:N14) -> 0 | P14: =IFERROR(SUMIF(p_dt_c_person,A14,p_dt_c_eff),0) -> 0
B15: =IFERROR(VLOOKUP(A15,r_dt_team,4, FALSE),0) -> 0 | C15: =P15-SUM(D15:J15) -> 0 | D15: =ROUND($P15/8,0) -> 0 | E15: =ROUND($P15/8,0) -> 0 | F15: =ROUND($P15/8,0) -> 0 | G15: =ROUND($P15/8,0) -> 0 | H15: =ROUND($P15/8,0) -> 0 | I15: =ROUND($P15/8,0) -> 0 | J15: =ROUND($P15/8,0) -> 0 | O15: =SUM(C15:N15) -> 0 | P15: =IFERROR(SUMIF(p_dt_c_person,A15,p_dt_c_eff),0) -> 0
B16: =IFERROR(VLOOKUP(A16,r_dt_team,4, FALSE),0) -> 0 | C16: =P16-SUM(D16:J16) -> 0 | D16: =ROUND($P16/8,0) -> 0 | E16: =ROUND($P16/8,0) -> 0 | F16: =ROUND($P16/8,0) -> 0 | G16: =ROUND($P16/8,0) -> 0 | H16: =ROUND($P16/8,0) -> 0 | I16: =ROUND($P16/8,0) -> 0 | J16: =ROUND($P16/8,0) -> 0 | O16: =SUM(C16:N16) -> 0 | P16: =IFERROR(SUMIF(p_dt_c_person,A16,p_dt_c_eff),0) -> 0
B17: =IFERROR(VLOOKUP(A17,r_dt_team,4, FALSE),0) -> 0 | C17: =P17-SUM(D17:J17) -> 0 | D17: =ROUND($P17/8,0) -> 0 | E17: =ROUND($P17/8,0) -> 0 | F17: =ROUND($P17/8,0) -> 0 | G17: =ROUND($P17/8,0) -> 0 | H17: =ROUND($P17/8,0) -> 0 | I17: =ROUND($P17/8,0) -> 0 | J17: =ROUND($P17/8,0) -> 0 | O17: =SUM(C17:N17) -> 0 | P17: =IFERROR(SUMIF(p_dt_c_person,A17,p_dt_c_eff),0) -> 0
B18: =IFERROR(VLOOKUP(A18,r_dt_team,4, FALSE),0) -> 0 | C18: =P18-SUM(D18:J18) -> 0 | D18: =ROUND($P18/8,0) -> 0 | E18: =ROUND($P18/8,0) -> 0 | F18: =ROUND($P18/8,0) -> 0 | G18: =ROUND($P18/8,0) -> 0 | H18: =ROUND($P18/8,0) -> 0 | I18: =ROUND($P18/8,0) -> 0 | J18: =ROUND($P18/8,0) -> 0 | O18: =SUM(C18:N18) -> 0 | P18: =IFERROR(SUMIF(p_dt_c_person,A18,p_dt_c_eff),0) -> 0
A20: Длит. Проекат | B20: 8
A22: Загрузка в процентах
A23: =A7 -> 0 | C23: =C7/21 -> 0 | D23: =D7/21 -> 0 | E23: =E7/21 -> 0 | F23: =F7/21 -> 0 | G23: =G7/21 -> 0 | H23: =H7/21 -> 0 | I23: =I7/21 -> 0 | J23: =J7/21 -> 0
A24: =A8 -> 0 | C24: =C8/21 -> 0 | D24: =D8/21 -> 0 | E24: =E8/21 -> 0 | F24: =F8/21 -> 0 | G24: =G8/21 -> 0 | H24: =H8/21 -> 0 | I24: =I8/21 -> 0 | J24: =J8/21 -> 0
A25: =A9 -> 0 | C25: =C9/21 -> 0 | D25: =D9/21 -> 0 | E25: =E9/21 -> 0 | F25: =F9/21 -> 0 | G25: =G9/21 -> 0 | H25: =H9/21 -> 0 | I25: =I9/21 -> 0 | J25: =J9/21 -> 0
A26: =A10 -> 0 | C26: =C10/21 -> 0 | D26: =D10/21 -> 0 | E26: =E10/21 -> 0 | F26: =F10/21 -> 0 | G26: =G10/21 -> 0 | H26: =H10/21 -> 0 | I26: =I10/21 -> 0 | J26: =J10/21 -> 0
A27: =A11 -> 0 | C27: =C11/21 -> 0 | D27: =D11/21 -> 0 | E27: =E11/21 -> 0 | F27: =F11/21 -> 0 | G27: =G11/21 -> 0 | H27: =H11/21 -> 0 | I27: =I11/21 -> 0 | J27: =J11/21 -> 0
A28: =A12 -> 0 | C28: =C12/21 -> 0 | D28: =D12/21 -> 0 | E28: =E12/21 -> 0 | F28: =F12/21 -> 0 | G28: =G12/21 -> 0 | H28: =H12/21 -> 0 | I28: =I12/21 -> 0 | J28: =J12/21 -> 0
A29: =A13 -> 0 | C29: =C13/21 -> 0 | D29: =D13/21 -> 0 | E29: =E13/21 -> 0 | F29: =F13/21 -> 0 | G29: =G13/21 -> 0 | H29: =H13/21 -> 0 | I29: =I13/21 -> 0 | J29: =J13/21 -> 0
A30: =A14 -> 0 | C30: =C14/21 -> 0 | D30: =D14/21 -> 0 | E30: =E14/21 -> 0 | F30: =F14/21 -> 0 | G30: =G14/21 -> 0 | H30: =H14/21 -> 0 | I30: =I14/21 -> 0 | J30: =J14/21 -> 0
A31: =A15 -> 0 | C31: =C15/21 -> 0 | D31: =D15/21 -> 0 | E31: =E15/21 -> 0 | F31: =F15/21 -> 0 | G31: =G15/21 -> 0 | H31: =H15/21 -> 0 | I31: =I15/21 -> 0 | J31: =J15/21 -> 0
A32: =A16 -> 0 | C32: =C16/21 -> 0 | D32: =D16/21 -> 0 | E32: =E16/21 -> 0 | F32: =F16/21 -> 0 | G32: =G16/21 -> 0 | H32: =H16/21 -> 0 | I32: =I16/21 -> 0 | J32: =J16/21 -> 0
A33: =A17 -> 0 | C33: =C17/21 -> 0 | D33: =D17/21 -> 0 | E33: =E17/21 -> 0 | F33: =F17/21 -> 0 | G33: =G17/21 -> 0 | H33: =H17/21 -> 0 | I33: =I17/21 -> 0 | J33: =J17/21 -> 0
A34: =A18 -> 0 | C34: =C18/21 -> 0 | D34: =D18/21 -> 0 | E34: =E18/21 -> 0 | F34: =F18/21 -> 0 | G34: =G18/21 -> 0 | H34: =H18/21 -> 0 | I34: =I18/21 -> 0 | J34: =J18/21 -> 0

Sheet ОПУ
A1: Текущая Дата | B1: ='Ставки и расходы'!D6 -> 0 | C1: Вероятность проекта | D1: 1
B3: ФАКТ (входящий) | C3: ФАКТ (проект) | D3: ФАКТ (год) | E3: =DATEVALUE("01/01/"&YEAR(ОПУ!B1)) -> 1 | F3: =EDATE(E3,1) -> 32 | G3: =EDATE(F3,1) -> 61 | H3: =EDATE(G3,1) -> 92 | I3: =EDATE(H3,1) -> 122 | J3: =EDATE(I3,1) -> 153 | K3: =EDATE(J3,1) -> 183 | L3: =EDATE(K3,1) -> 214 | M3: =EDATE(L3,1) -> 245 | ... P3: =EDATE(O3,1) -> 336 | Q3: ИТОГО (остаток) | R3: ИТОГО (год) | S3: ИТОГО (проект) | T3: ИТОГО (план)
A4: Этап проекта | E4: Э1 | F4: Э1 | G4: Э1 | H4: Э2
A5: Вероятность
A6: Акты | E6: 1 | F6: 1 | G6: 1 | H6: 1 | I6: 1 | J6: 1 | K6: 1 | L6: 1 | M6: 1 | N6: 1 | O6: 1 | P6: 1
A7: Расходы, собственные | E7: 1 | F7: 1 | G7: 1 | H7: 1 | I7: 1 | J7: 1 | K7: 1 | L7: 1 | M7: 1 | N7: 1 | O7: 1 | P7: 1
A8: Расходы, субподряд | E8: 1 | F8: 1 | G8: 1 | H8: 1 | I8: 1 | J8: 1 | K8: 1 | L8: 1 | M8: 1 | N8: 1 | O8: 1 | P8: 1
A9: Расходы, группа компаний | E9: 1 | F9: 1 | G9: 1 | H9: 1 | I9: 1 | J9: 1 | K9: 1 | L9: 1 | M9: 1 | N9: 1 | O9: 1 | P9: 1
A10: Оплата | E10: 1 | F10: 1 | G10: 1 | H10: 1 | I10: 1 | J10: 1 | K10: 1 | L10: 1 | M10: 1 | N10: 1 | O10: 1 | P10: 1
A11: Выручка (взвешенная) | B11: =B15 -> 0 | C11: =B11+D11 -> 0 | D11: =SUMIFS(E11:P11,$E$3:$P$3,"<" & $B$1) -> 0 | E11: =SUM(E12:E14) -> 0 | F11: =SUM(F12:F14) -> 0 | G11: =SUM(G12:G14) -> 0 | H11: =SUM(H12:H14) -> 0 | I11: =SUM(I12:I14) -> 0 | J11: =SUM(J12:J14) -> 0 | K11: =SUM(K12:K14) -> 0 | L11: =SUM(L12:L14) -> 0 | ... P11: =SUM(P12:P14) -> 0 | Q11: =SUMIFS(E11:P11,$E$3:$P$3,">=" & $B$1) -> 0 | R11: =Q11+D11 -> 0 | S11: =Q11+C11 -> 0
A12: Собственные | C12: =B12+D12 -> 0 | D12: =SUMIFS(E12:P12,$E$3:$P$3,"<" & $B$1) -> 0 | E12: =E16*E$6*$D$1 -> 0 | F12: =F16*F$6*$D$1 -> 0 | G12: =G16*G$6*$D$1 -> 0 | H12: =H16*H$6*$D$1 -> 0 | I12: =I16*I$6*$D$1 -> 0 | J12: =J16*J$6*$D$1 -> 0 | K12: =K16*K$6*$D$1 -> 0 | L12: =L16*L$6*$D$1 -> 0 | ... P12: =P16*P$6*$D$1 -> 0 | Q12: =SUMIFS(E12:P12,$E$3:$P$3,">=" & $B$1) -> 0 | R12: =Q12+D12 -> 0 | S12: =Q12+C12 -> 0
A13: Субподряд | C13: =B13+D13 -> 0 | D13: =SUMIFS(E13:P13,$E$3:$P$3,"<" & $B$1) -> 0 | E13: =E17*E$6*$D$1 -> 0 | F13: =F17*F$6*$D$1 -> 0 | G13: =G17*G$6*$D$1 -> 0 | H13: =H17*H$6*$D$1 -> 0 | I13: =I17*I$6*$D$1 -> 0 | J13: =J17*J$6*$D$1 -> 0 | K13: =K17*K$6*$D$1 -> 0 | L13: =L17*L$6*$D$1 -> 0 | ... P13: =P17*P$6*$D$1 -> 0 | Q13: =SUMIFS(E13:P13,$E$3:$P$3,">=" & $B$1) -> 0 | R13: =Q13+D13 -> 0 | S13: =Q13+C13 -> 0
A14: Группа компаний | C14: =B14+D14 -> 0 | D14: =SUMIFS(E14:P14,$E$3:$P$3,"<" & $B$1) -> 0 | E14: =E18*E$6*$D$1 -> 0 | F14: =F18*F$6*$D$1 -> 0 | G14: =G18*G$6*$D$1 -> 0 | H14: =H18*H$6*$D$1 -> 0 | I14: =I18*I$6*$D$1 -> 0 | J14: =J18*J$6*$D$1 -> 0 | K14: =K18*K$6*$D$1 -> 0 | L14: =L18*L$6*$D$1 -> 0 | ... P14: =P18*P$6*$D$1 -> 0 | Q14: =SUMIFS(E14:P14,$E$3:$P$3,">=" & $B$1) -> 0 | R14: =Q14+D14 -> 0 | S14: =Q14+C14 -> 0
A15: Акты | B15: 0 | C15: =B15+D15 -> 0 | D15: =SUMIFS(E15:P15,$E$3:$P$3,"<" & $B$1) -> 0 | E15: 0 | F15: 0 | G15: 0 | H15: 0 | I15: 0 | J15: 0 | K15: 0 | L15: 0 | M15: 0 | N15: 0 | O15: 0 | P15: 0 | Q15: =SUMIFS(E15:P15,$E$3:$P$3,">=" & $B$1) -> 0 | R15: =Q15+D15 -> 0 | S15: =Q15+C15 -> 0 | T15: ='Калькулятор бюджета по этапам'!M12 -> 0
A16: Собственные | C16: =B16+D16 -> 0 | D16: =SUMIFS(E16:P16,$E$3:$P$3,"<" & $B$1) -> 0 | E16: =IF(IFERROR(HLOOKUP(E4,'Калькулятор бюджета по этапам'!$E$7:$L$15,6,FALSE),0)>0, IFERROR(HLOOKUP(E4,'Калькулятор бюджета по этапам'!$E$7:$L$15,7,FALSE),0)/HLOOKUP(E4,'Калькулятор бюджета по этапам'!$E$7:$L$15,6,FALSE),0)*E$15 -> 0 | F16: =IF(IFERROR(HLOOKUP(F4,'Калькулятор бюджета по этапам'!$E$7:$L$15,6,FALSE),0)>0, IFERROR(HLOOKUP(F4,'Калькулятор бюджета по этапам'!$E$7:$L$15,7,FALSE),0)/HLOOKUP(F4,'Калькулятор бюджета по этапам'!$E$7:$L$15,6,FALSE),0)*F$15 -> 0 | G16: =IF(IFERROR(HLOOKUP(G4,'Калькулятор бюджета по этапам'!$E$7:$L$15,6,FALSE),0)>0, IFERROR(HLOOKUP(G4,'Калькулятор бюджета по этапам'!$E$7:$L$15,7,FALSE),0)/HLOOKUP(G4,'Калькулятор бюджета по этапам'!$E$7:$L$15,6,FALSE),0)*G$15 -> 0 | H16: =IF(IFERROR(HLOOKUP(H4,'Калькулятор бюджета по этапам'!$E$7:$L$15,6,FALSE),0)>0, IFERROR(HLOOKUP(H4,'Калькулятор бюджета по этапам'!$E$7:$L$15,7,FALSE),0)/HLOOKUP(H4,'Калькулятор бюджета по этапам'!$E$7:$L$15,6,FALSE),0)*H$15 -> 0 | I16: =IF(IFERROR(HLOOKUP(I4,'Калькулятор бюджета по этапам'!$E$7:$L$15,6,FALSE),0)>0, IFERROR(HLOOKUP(I4,'Калькулятор бюджета по этапам'!$E$7:$L$15,7,FALSE),0)/HLOOKUP(I4,'Калькулятор бюджета по этапам'!$E$7:$L$15,6,FALSE),0)*I$15 -> 0 | J16: =IF(IFERROR(HLOOKUP(J4,'Калькулятор бюджета по этапам'!$E$7:$L$15,6,FALSE),0)>0, IFERROR(HLOOKUP(J4,'Калькулятор бюджета по этапам'!$E$7:$L$15,7,FALSE),0)/HLOOKUP(J4,'Калькулятор бюджета по этапам'!$E$7:$L$15,6,FALSE),0)*J$15 -> 0 | K16: =IF(IFERROR(HLOOKUP(K4,'Калькулятор бюджета по этапам'!$E$7:$L$15,6,FALSE),0)>0, IFERROR(HLOOKUP(K4,'Калькулятор бюджета по этапам'!$E$7:$L$15,7,FALSE),0)/HLOOKUP(K4,'Калькулятор бюджета по этапам'!$E$7:$L$15,6,FALSE),0)*K$15 -> 0 | L16: =IF(IFERROR(HLOOKUP(L4,'Калькулятор бюджета по этапам'!$E$7:$L$15,6,FALSE),0)>0, IFERROR(HLOOKUP(L4,'Калькулятор бюджета по этапам'!$E$7:$L$15,7,FALSE),0)/HLOOKUP(L4,'Калькулятор бюджета по этапам'!$E$7:$L$15,6,FALSE),0)*L$15 -> 0 | ... P16: =IF(IFERROR(HLOOKUP(P4,'Калькулятор бюджета по этапам'!$E$7:$L$15,6,FALSE),0)>0, IFERROR(HLOOKUP(P4,'Калькулятор бюджета по этапам'!$E$7:$L$15,7,FALSE),0)/HLOOKUP(P4,'Калькулятор бюджета по этапам'!$E$7:$L$15,6,FALSE),0)*P$15 -> 0 | Q16: =SUMIFS(E16:P16,$E$3:$P$3,">=" & $B$1) -> 0 | R16: =Q16+D16 -> 0 | S16: =Q16+C16 -> 0 | T16: ='Калькулятор бюджета по этапам'!M13 -> 0
A17: Субподряд | C17: =B17+D17 -> 0 | D17: =SUMIFS(E17:P17,$E$3:$P$3,"<" & $B$1) -> 0 | E17: =IF(IFERROR(HLOOKUP(E4,'Калькулятор бюджета по этапам'!$E$7:$L$15,6,FALSE),0)>0, IFERROR(HLOOKUP(E4,'Калькулятор бюджета по этапам'!$E$7:$L$15,8,FALSE),0)/HLOOKUP(E4,'Калькулятор бюджета по этапам'!$E$7:$L$15,6,FALSE),0)*E$15 -> 0 | F17: =IF(IFERROR(HLOOKUP(F4,'Калькулятор бюджета по этапам'!$E$7:$L$15,6,FALSE),0)>0, IFERROR(HLOOKUP(F4,'Калькулятор бюджета по этапам'!$E$7:$L$15,8,FALSE),0)/HLOOKUP(F4,'Калькулятор бюджета по этапам'!$E$7:$L$15,6,FALSE),0)*F$15 -> 0 | G17: =IF(IFERROR(HLOOKUP(G4,'Калькулятор бюджета по этапам'!$E$7:$L$15,6,FALSE),0)>0, IFERROR(HLOOKUP(G4,'Калькулятор бюджета по этапам'!$E$7:$L$15,8,FALSE),0)/HLOOKUP(G4,'Калькулятор бюджета по этапам'!$E$7:$L$15,6,FALSE),0)*G$15 -> 0 | H17: =IF(IFERROR(HLOOKUP(H4,'Калькулятор бюджета по этапам'!$E$7:$L$15,6,FALSE),0)>0, IFERROR(HLOOKUP(H4,'Калькулятор бюджета по этапам'!$E$7:$L$15,8,FALSE),0)/HLOOKUP(H4,'Калькулятор бюджета по этапам'!$E$7:$L$15,6,FALSE),0)*H$15 -> 0 | I17: =IF(IFERROR(HLOOKUP(I4,'Калькулятор бюджета по этапам'!$E$7:$L$15,6,FALSE),0)>0, IFERROR(HLOOKUP(I4,'Калькулятор бюджета по этапам'!$E$7:$L$15,8,FALSE),0)/HLOOKUP(I4,'Калькулятор бюджета по этапам'!$E$7:$L$15,6,FALSE),0)*I$15 -> 0 | J17: =IF(IFERROR(HLOOKUP(J4,'Калькулятор бюджета по этапам'!$E$7:$L$15,6,FALSE),0)>0, IFERROR(HLOOKUP(J4,'Калькулятор бюджета по этапам'!$E$7:$L$15,8,FALSE),0)/HLOOKUP(J4,'Калькулятор бюджета по этапам'!$E$7:$L$15,6,FALSE),0)*J$15 -> 0 | K17: =IF(IFERROR(HLOOKUP(K4,'Калькулятор бюджета по этапам'!$E$7:$L$15,6,FALSE),0)>0, IFERROR(HLOOKUP(K4,'Калькулятор бюджета по этапам'!$E$7:$L$15,8,FALSE),0)/HLOOKUP(K4,'Калькулятор бюджета по этапам'!$E$7:$L$15,6,FALSE),0)*K$15 -> 0 | L17: =IF(IFERROR(HLOOKUP(L4,'Калькулятор бюджета по этапам'!$E$7:$L$15,6,FALSE),0)>0, IFERROR(HLOOKUP(L4,'Калькулятор бюджета по этапам'!$E$7:$L$15,8,FALSE),0)/HLOOKUP(L4,'Калькулятор бюджета по этапам'!$E$7:$L$15,6,FALSE),0)*L$15 -> 0 | ... P17: =IF(IFERROR(HLOOKUP(P4,'Калькулятор бюджета по этапам'!$E$7:$L$15,6,FALSE),0)>0, IFERROR(HLOOKUP(P4,'Калькулятор бюджета по этапам'!$E$7:$L$15,8,FALSE),0)/HLOOKUP(P4,'Калькулятор бюджета по этапам'!$E$7:$L$15,6,FALSE),0)*P$15 -> 0 | Q17: =SUMIFS(E17:P17,$E$3:$P$3,">=" & $B$1) -> 0 | R17: =Q17+D17 -> 0 | S17: =Q17+C17 -> 0 | T17: ='Калькулятор бюджета по этапам'!M14 -> 0
A18: Группа компаний | C18: =B18+D18 -> 0 | D18: =SUMIFS(E18:P18,$E$3:$P$3,"<" & $B$1) -> 0 | E18: =IF(IFERROR(HLOOKUP(E4,'Калькулятор бюджета по этапам'!$E$7:$L$15,6,FALSE),0)>0, IFERROR(HLOOKUP(E4,'Калькулятор бюджета по этапам'!$E$7:$L$15,9,FALSE),0)/HLOOKUP(E4,'Калькулятор бюджета по этапам'!$E$7:$L$15,6,FALSE),0)*E$15 -> 0 | F18: =IF(IFERROR(HLOOKUP(F4,'Калькулятор бюджета по этапам'!$E$7:$L$15,6,FALSE),0)>0, IFERROR(HLOOKUP(F4,'Калькулятор бюджета по этапам'!$E$7:$L$15,9,FALSE),0)/HLOOKUP(F4,'Калькулятор бюджета по этапам'!$E$7:$L$15,6,FALSE),0)*F$15 -> 0 | G18: =IF(IFERROR(HLOOKUP(G4,'Калькулятор бюджета по этапам'!$E$7:$L$15,6,FALSE),0)>0, IFERROR(HLOOKUP(G4,'Калькулятор бюджета по этапам'!$E$7:$L$15,9,FALSE),0)/HLOOKUP(G4,'Калькулятор бюджета по этапам'!$E$7:$L$15,6,FALSE),0)*G$15 -> 0 | H18: =IF(IFERROR(HLOOKUP(H4,'Калькулятор бюджета по этапам'!$E$7:$L$15,6,FALSE),0)>0, IFERROR(HLOOKUP(H4,'Калькулятор бюджета по этапам'!$E$7:$L$15,9,FALSE),0)/HLOOKUP(H4,'Калькулятор бюджета по этапам'!$E$7:$L$15,6,FALSE),0)*H$15 -> 0 | I18: =IF(IFERROR(HLOOKUP(I4,'Калькулятор бюджета по этапам'!$E$7:$L$15,6,FALSE),0)>0, IFERROR(HLOOKUP(I4,'Калькулятор бюджета по этапам'!$E$7:$L$15,9,FALSE),0)/HLOOKUP(I4,'Калькулятор бюджета по этапам'!$E$7:$L$15,6,FALSE),0)*I$15 -> 0 | J18: =IF(IFERROR(HLOOKUP(J4,'Калькулятор бюджета по этапам'!$E$7:$L$15,6,FALSE),0)>0, IFERROR(HLOOKUP(J4,'Калькулятор бюджета по этапам'!$E$7:$L$15,9,FALSE),0)/HLOOKUP(J4,'Калькулятор бюджета по этапам'!$E$7:$L$15,6,FALSE),0)*J$15 -> 0 | K18: =IF(IFERROR(HLOOKUP(K4,'Калькулятор бюджета по этапам'!$E$7:$L$15,6,FALSE),0)>0, IFERROR(HLOOKUP(K4,'Калькулятор бюджета по этапам'!$E$7:$L$15,9,FALSE),0)/HLOOKUP(K4,'Калькулятор бюджета по этапам'!$E$7:$L$15,6,FALSE),0)*K$15 -> 0 | L18: =IF(IFERROR(HLOOKUP(L4,'Калькулятор бюджета по этапам'!$E$7:$L$15,6,FALSE),0)>0, IFERROR(HLOOKUP(L4,'Калькулятор бюджета по этапам'!$E$7:$L$15,9,FALSE),0)/HLOOKUP(L4,'Калькулятор бюджета по этапам'!$E$7:$L$15,6,FALSE),0)*L$15 -> 0 | ... P18: =IF(IFERROR(HLOOKUP(P4,'Калькулятор бюджета по этапам'!$E$7:$L$15,6,FALSE),0)>0, IFERROR(HLOOKUP(P4,'Калькулятор бюджета по этапам'!$E$7:$L$15,9,FALSE),0)/HLOOKUP(P4,'Калькулятор бюджета по этапам'!$E$7:$L$15,6,FALSE),0)*P$15 -> 0 | Q18: =SUMIFS(E18:P18,$E$3:$P$3,">=" & $B$1) -> 0 | R18: =Q18+D18 -> 0 | S18: =Q18+C18 -> 0 | T18: ='Калькулятор бюджета по этапам'!M15 -> 0
