Workbook

Sheet Трудозатраты
B1: Этапы | C1: Фазы | E1: Драйверы трудозатрат | F1: Проанализировать драйвер и заполнить поле для оценки | I1: Трудозатраты Ч/Д. (Расчитывается, как Норматив * коэффициент драйверов) | S1: Норматив
I2: Роли | S2: Роли
F3: Простой | G3: Средний | H3: Сложный | I3: PM | J3: DS Senior | K3: DS middle | L3: Arch | M3: BI | N3: Data Engineer | O3: Ops (Dev/ML) | P3: BusinAnalust | Q3: Результат | R3: Документы | S3: PM | T3: DS Senior | U3: DS middle | V3: Arch | W3: BI | X3: Data Engi. | Y3: Ops (Dev/ML) | Z3: Business Analust*
I4: К2 | J4: К3 | K4: К2 | L4: К4 | M4: К3 | N4: К3 | O4: К4 | P4: К2
I5: =VLOOKUP(I4,Настройки!$A$26:$E$31,5,0) -> 23120 | J5: =VLOOKUP(J4,Настройки!$A$26:$E$31,5,0) -> 31280 | K5: =VLOOKUP(K4,Настройки!$A$26:$E$31,5,0) -> 23120 | L5: =VLOOKUP(L4,Настройки!$A$26:$E$31,5,0) -> 41760 | M5: =VLOOKUP(M4,Настройки!$A$26:$E$31,5,0) -> 31280 | N5: =VLOOKUP(N4,Настройки!$A$26:$E$31,5,0) -> 31280 | O5: =VLOOKUP(O4,Настройки!$A$26:$E$31,5,0) -> 41760 | P5: =VLOOKUP(P4,Настройки!$A$26:$E$31,5,0) -> 23120
E6: Бизнес домены данных. Указать количество в разрезе их сложности. | F6: 1
E7: Количество и сложность источников данных (API, РестФулл, …). Указать количество в разрезе их сложности. | F7: 1
E8: Уровень сложности проекта. Указать уровень сложности. | F8: х
E9: Количество и сложность модели. Указать количество в разрезе их сложности. | F9: 1
E10: По количеству WorkFlow процессов. Указать количество в разрезе их сложности. | F10: 1
B11: Этап 0. Подготовка инфраструктуры | I11: =SUM(I12:I16) -> 3 | J11: =SUM(J12:J16) -> 9.75 | K11: =SUM(K12:K16) -> 9 | L11: =SUM(L12:L16) -> 6.75 | M11: =SUM(M12:M16) -> 5.5 | N11: =SUM(N12:N16) -> 7.5 | O11: =SUM(O12:O16) -> 13.25 | P11: =SUM(P12:P16) -> 0 | Q11: Факт досупности выч.мощности Развернутая и готовая среда Коннектеры настроены
C12: Выделение вычислительных мощностей (~ core64, RAM 80GB, ssd 5 TB, 2*GPU nVidia A100/V100) | E12: Указать уровень сложности, где: Простой - инфраструктура полностью на своих серверах и ПО уже готово к работе Средний - Необходимо поддерживать ПО у заказчика или необходимо донастроить ПО на своих серверах Сложный - необходимо установить и поддерживать ПО у заказчика | H12: х | I12: =IFERROR(S12*_xlfn.IFS($F$12<>"",0,$G$12<>"",0.5,$H$12<>"",1),0) -> 2 | J12: =IFERROR(T12*_xlfn.IFS($F$12<>"",0,$G$12<>"",0.5,$H$12<>"",1),0) -> 0.75 | K12: =IFERROR(U12*_xlfn.IFS($F$12<>"",0,$G$12<>"",0.5,$H$12<>"",1),0) -> 0 | L12: =IFERROR(V12*_xlfn.IFS($F$12<>"",0,$G$12<>"",0.5,$H$12<>"",1),0) -> 0.75 | M12: =IFERROR(W12*_xlfn.IFS($F$12<>"",0,$G$12<>"",0.5,$H$12<>"",1),0) -> 0 | N12: =IFERROR(X12*_xlfn.IFS($F$12<>"",0,$G$12<>"",0.5,$H$12<>"",1),0) -> 0 | O12: =IFERROR(Y12*_xlfn.IFS($F$12<>"",0,$G$12<>"",0.5,$H$12<>"",1),0) -> 0.75 | P12: =IFERROR(Z12*_xlfn.IFS($F$12<>"",0,$G$12<>"",0.5,$H$12<>"",1),0) -> 0 | S12: 2 | T12: 0.75 | U12: 0 | V12: 0.75 | W12: 0 | X12: 0 | Y12: 0.75 | Z12: 0
C13: Подготовка среды: MLOps, minio | I13: =IFERROR(S13*_xlfn.IFS($F$12<>"",0,$G$12<>"",0.5,$H$12<>"",1),0) -> 0 | J13: =IFERROR(T13*_xlfn.IFS($F$12<>"",0,$G$12<>"",0.5,$H$12<>"",1),0) -> 3.5 | K13: =IFERROR(U13*_xlfn.IFS($F$12<>"",0,$G$12<>"",0.5,$H$12<>"",1),0) -> 3.5 | L13: =IFERROR(V13*_xlfn.IFS($F$12<>"",0,$G$12<>"",0.5,$H$12<>"",1),0) -> 2 | M13: =IFERROR(W13*_xlfn.IFS($F$12<>"",0,$G$12<>"",0.5,$H$12<>"",1),0) -> 0 | N13: =IFERROR(X13*_xlfn.IFS($F$12<>"",0,$G$12<>"",0.5,$H$12<>"",1),0) -> 0 | O13: =IFERROR(Y13*_xlfn.IFS($F$12<>"",0,$G$12<>"",0.5,$H$12<>"",1),0) -> 3.5 | P13: =IFERROR(Z13*_xlfn.IFS($F$12<>"",0,$G$12<>"",0.5,$H$12<>"",1),0) -> 0 | T13: 3.5 | U13: 3.5 | V13: 2 | W13: 0 | X13: 0 | Y13: 3.5 | Z13: 0
C14: Подготовка среды разработки hadoop, hive, spark, AirFlow, NiFi/kafka/RabbitMQ/Redis, JupyterLab | I14: =IFERROR(S14*_xlfn.IFS($F$12<>"",0,$G$12<>"",0.5,$H$12<>"",1),0) -> 0 | J14: =IFERROR(T14*_xlfn.IFS($F$12<>"",0,$G$12<>"",0.5,$H$12<>"",1),0) -> 3.5 | K14: =IFERROR(U14*_xlfn.IFS($F$12<>"",0,$G$12<>"",0.5,$H$12<>"",1),0) -> 3.5 | L14: =IFERROR(V14*_xlfn.IFS($F$12<>"",0,$G$12<>"",0.5,$H$12<>"",1),0) -> 1 | M14: =IFERROR(W14*_xlfn.IFS($F$12<>"",0,$G$12<>"",0.5,$H$12<>"",1),0) -> 3.5 | N14: =IFERROR(X14*_xlfn.IFS($F$12<>"",0,$G$12<>"",0.5,$H$12<>"",1),0) -> 2 | O14: =IFERROR(Y14*_xlfn.IFS($F$12<>"",0,$G$12<>"",0.5,$H$12<>"",1),0) -> 3.5 | P14: =IFERROR(Z14*_xlfn.IFS($F$12<>"",0,$G$12<>"",0.5,$H$12<>"",1),0) -> 0 | T14: 3.5 | U14: 3.5 | V14: 1 | W14: 3.5 | X14: 2 | Y14: 3.5 | Z14: 0
C15: Настройка коннекторов к доменам источников данных (два главных источник – SQL Server + Фед ресурс) | I15: =IFERROR(S15*_xlfn.IFS($F$12<>"",0,$G$12<>"",0.5,$H$12<>"",1),0) -> 0.25 | J15: =IFERROR(T15*_xlfn.IFS($F$12<>"",0,$G$12<>"",0.5,$H$12<>"",1),0) -> 0 | K15: =IFERROR(U15*_xlfn.IFS($F$12<>"",0,$G$12<>"",0.5,$H$12<>"",1),0) -> 0 | L15: =IFERROR(V15*_xlfn.IFS($F$12<>"",0,$G$12<>"",0.5,$H$12<>"",1),0) -> 1 | M15: =IFERROR(W15*_xlfn.IFS($F$12<>"",0,$G$12<>"",0.5,$H$12<>"",1),0) -> 0 | N15: =IFERROR(X15*_xlfn.IFS($F$12<>"",0,$G$12<>"",0.5,$H$12<>"",1),0) -> 3.5 | O15: =IFERROR(Y15*_xlfn.IFS($F$12<>"",0,$G$12<>"",0.5,$H$12<>"",1),0) -> 3.5 | P15: =IFERROR(Z15*_xlfn.IFS($F$12<>"",0,$G$12<>"",0.5,$H$12<>"",1),0) -> 0 | S15: 0.25 | T15: 0 | U15: 0 | V15: 1 | W15: 0 | X15: 3.5 | Y15: 3.5 | Z15: 0
C16: Интеграция всех компонентов среды | I16: =IFERROR(S16*_xlfn.IFS($F$12<>"",0,$G$12<>"",0.5,$H$12<>"",1),0) -> 0.75 | J16: =IFERROR(T16*_xlfn.IFS($F$12<>"",0,$G$12<>"",0.5,$H$12<>"",1),0) -> 2 | K16: =IFERROR(U16*_xlfn.IFS($F$12<>"",0,$G$12<>"",0.5,$H$12<>"",1),0) -> 2 | L16: =IFERROR(V16*_xlfn.IFS($F$12<>"",0,$G$12<>"",0.5,$H$12<>"",1),0) -> 2 | M16: =IFERROR(W16*_xlfn.IFS($F$12<>"",0,$G$12<>"",0.5,$H$12<>"",1),0) -> 2 | N16: =IFERROR(X16*_xlfn.IFS($F$12<>"",0,$G$12<>"",0.5,$H$12<>"",1),0) -> 2 | O16: =IFERROR(Y16*_xlfn.IFS($F$12<>"",0,$G$12<>"",0.5,$H$12<>"",1),0) -> 2 | P16: =IFERROR(Z16*_xlfn.IFS($F$12<>"",0,$G$12<>"",0.5,$H$12<>"",1),0) -> 0 | S16: 0.75 | T16: 2 | U16: 2 | V16: 2 | W16: 2 | X16: 2 | Y16: 2 | Z16: 0
B17: Этап 1: Подготовка и планирование | I17: =SUM(I18) -> 3 | J17: =SUM(J18) -> 5 | K17: =SUM(K18) -> 5 | L17: =SUM(L18) -> 3 | M17: =SUM(M18) -> 1 | N17: =SUM(N18) -> 0 | O17: =SUM(O18) -> 0 | P17: =SUM(P18) -> 5 | Q17: Определены ресурсы Матрица рисков Определена типы моделей и алгоритмы ML Определены технические характеристики и стеки технологий для ML, мощьности, среда хранилища данных. Определен набор инструментов для управления моделями машинного обучения и платформа для размети/управления данными, система для управления версионностью, среда разработки и фреймворки | R17: Детальный календарный план-график проекта Отчёт об анализе
C18: 1. Оценка времени на исследование и анализ | E18: Бизнес домены данных | F18: =F6 -> 1 | G18: =G6 -> 0 | H18: =H6 -> 0 | I18: =IFERROR(VLOOKUP(_xlfn.IFS((Настройки!$C$3*$F18+Настройки!$D$3*$G18+Настройки!$E$3*$H18)<=VLOOKUP(Настройки!$K$3,Настройки!$H:$I,2,0),(Настройки!$C$3*$F18+Настройки!$D$3*$G18+Настройки!$E$3*$H18),(Настройки!$C$3*$F18+Настройки!$D$3*$G18+Настройки!$E$3*$H18)>VLOOKUP(Настройки!$K$3,Настройки!$H:$I,2,0),VLOOKUP(Настройки!$K$3,Настройки!$H:$I,2,0)),Настройки!$I:$J,2,0)*S18,0) -> 3 | J18: =IFERROR(VLOOKUP(_xlfn.IFS((Настройки!$C$3*$F18+Настройки!$D$3*$G18+Настройки!$E$3*$H18)<=VLOOKUP(Настройки!$K$3,Настройки!$H:$I,2,0),(Настройки!$C$3*$F18+Настройки!$D$3*$G18+Настройки!$E$3*$H18),(Настройки!$C$3*$F18+Настройки!$D$3*$G18+Настройки!$E$3*$H18)>VLOOKUP(Настройки!$K$3,Настройки!$H:$I,2,0),VLOOKUP(Настройки!$K$3,Настройки!$H:$I,2,0)),Настройки!$I:$J,2,0)*T18,0) -> 5 | K18: =IFERROR(VLOOKUP(_xlfn.IFS((Настройки!$C$3*$F18+Настройки!$D$3*$G18+Настройки!$E$3*$H18)<=VLOOKUP(Настройки!$K$3,Настройки!$H:$I,2,0),(Настройки!$C$3*$F18+Настройки!$D$3*$G18+Настройки!$E$3*$H18),(Настройки!$C$3*$F18+Настройки!$D$3*$G18+Настройки!$E$3*$H18)>VLOOKUP(Настройки!$K$3,Настройки!$H:$I,2,0),VLOOKUP(Настройки!$K$3,Настройки!$H:$I,2,0)),Настройки!$I:$J,2,0)*U18,0) -> 5 | L18: =IFERROR(VLOOKUP(_xlfn.IFS((Настройки!$C$3*$F18+Настройки!$D$3*$G18+Настройки!$E$3*$H18)<=VLOOKUP(Настройки!$K$3,Настройки!$H:$I,2,0),(Настройки!$C$3*$F18+Настройки!$D$3*$G18+Настройки!$E$3*$H18),(Настройки!$C$3*$F18+Настройки!$D$3*$G18+Настройки!$E$3*$H18)>VLOOKUP(Настройки!$K$3,Настройки!$H:$I,2,0),VLOOKUP(Настройки!$K$3,Настройки!$H:$I,2,0)),Настройки!$I:$J,2,0)*V18,0) -> 3 | M18: =IFERROR(VLOOKUP(_xlfn.IFS((Настройки!$C$3*$F18+Настройки!$D$3*$G18+Настройки!$E$3*$H18)<=VLOOKUP(Настройки!$K$3,Настройки!$H:$I,2,0),(Настройки!$C$3*$F18+Настройки!$D$3*$G18+Настройки!$E$3*$H18),(Настройки!$C$3*$F18+Настройки!$D$3*$G18+Настройки!$E$3*$H18)>VLOOKUP(Настройки!$K$3,Настройки!$H:$I,2,0),VLOOKUP(Настройки!$K$3,Настройки!$H:$I,2,0)),Настройки!$I:$J,2,0)*W18,0) -> 1 | N18: =IFERROR(VLOOKUP(_xlfn.IFS((Настройки!$C$3*$F18+Настройки!$D$3*$G18+Настройки!$E$3*$H18)<=VLOOKUP(Настройки!$K$3,Настройки!$H:$I,2,0),(Настройки!$C$3*$F18+Настройки!$D$3*$G18+Настройки!$E$3*$H18),(Настройки!$C$3*$F18+Настройки!$D$3*$G18+Настройки!$E$3*$H18)>VLOOKUP(Настройки!$K$3,Настройки!$H:$I,2,0),VLOOKUP(Настройки!$K$3,Настройки!$H:$I,2,0)),Настройки!$I:$J,2,0)*X18,0) -> 0 | O18: =IFERROR(VLOOKUP(_xlfn.IFS((Настройки!$C$3*$F18+Настройки!$D$3*$G18+Настройки!$E$3*$H18)<=VLOOKUP(Настройки!$K$3,Настройки!$H:$I,2,0),(Настройки!$C$3*$F18+Настройки!$D$3*$G18+Настройки!$E$3*$H18),(Настройки!$C$3*$F18+Настройки!$D$3*$G18+Настройки!$E$3*$H18)>VLOOKUP(Настройки!$K$3,Настройки!$H:$I,2,0),VLOOKUP(Настройки!$K$3,Настройки!$H:$I,2,0)),Настройки!$I:$J,2,0)*Y18,0) -> 0 | P18: =IFERROR(VLOOKUP(_xlfn.IFS((Настройки!$C$3*$F18+Настройки!$D$3*$G18+Настройки!$E$3*$H18)<=VLOOKUP(Настройки!$K$3,Настройки!$H:$I,2,0),(Настройки!$C$3*$F18+Настройки!$D$3*$G18+Настройки!$E$3*$H18),(Настройки!$C$3*$F18+Настройки!$D$3*$G18+Настройки!$E$3*$H18)>VLOOKUP(Настройки!$K$3,Настройки!$H:$I,2,0),VLOOKUP(Настройки!$K$3,Настройки!$H:$I,2,0)),Настройки!$I:$J,2,0)*Z18,0) -> 5 | S18: 3 | T18: 5 | U18: 5 | V18: 3 | W18: 1 | Z18: 5
B19: Этап 2: Сбор и анализ данных | I19: =SUM(I20:I26) -> 2.25 | J19: =SUM(J20:J26) -> 19 | K19: =SUM(K20:K26) -> 16 | L19: =SUM(L20:L26) -> 6 | M19: =SUM(M20:M26) -> 1 | N19: =SUM(N20:N26) -> 15 | O19: =SUM(O20:O26) -> 1 | P19: =SUM(P20:P26) -> 2 | Q19: Получены данные от заказчика Проанализирован объём и характеристики исходных данных Оценено качество достаточности и валидации данных Проведен анализ исходных данных на предмет их качества разметки Определены источники данных в инфраструктуре и способы их сбора Скрипты захвата, сбора и валидации и трансформации исходных данных Ссылки на репозитарий, объектное хранилище, БД. | R19: Карта источников данных Описательная статистика по источникам данных Метрики (отчёт) качества данных (полнота, достоверность …) Протокол по готовности моделирования данных
C20: 2. Определение источников данных в инфраструктуре и внешних источниках | E20: Количество и сложность источников данных | F20: =F7 -> 1 | G20: 2 | H20: 3 | I20: =IFERROR((VLOOKUP(SUMPRODUCT($F$20:$H$20,Настройки!$C$12:$E$12),Настройки!$N:$O,2,0))*S20,0) -> 1 | J20: =IFERROR((VLOOKUP(SUMPRODUCT($F$20:$H$20,Настройки!$C$12:$E$12),Настройки!$N:$O,2,0))*T20,0) -> 4 | K20: =IFERROR((VLOOKUP(SUMPRODUCT($F$20:$H$20,Настройки!$C$12:$E$12),Настройки!$N:$O,2,0))*U20,0) -> 2 | L20: =IFERROR((VLOOKUP(SUMPRODUCT($F$20:$H$20,Настройки!$C$12:$E$12),Настройки!$N:$O,2,0))*V20,0) -> 1 | M20: =IFERROR((VLOOKUP(SUMPRODUCT($F$20:$H$20,Настройки!$C$12:$E$12),Настройки!$N:$O,2,0))*W20,0) -> 0 | N20: =IFERROR((VLOOKUP(SUMPRODUCT($F$20:$H$20,Настройки!$C$12:$E$12),Настройки!$N:$O,2,0))*X20,0) -> 0 | O20: =IFERROR((VLOOKUP(SUMPRODUCT($F$20:$H$20,Настройки!$C$12:$E$12),Настройки!$N:$O,2,0))*Y20,0) -> 0 | P20: =IFERROR((VLOOKUP(SUMPRODUCT($F$20:$H$20,Настройки!$C$12:$E$12),Настройки!$N:$O,2,0))*Z20,0) -> 2 | S20: 0.25 | T20: 1 | U20: 0.5 | V20: 0.25 | Z20: 0.5
C21: 3. Разработка стратегии сбора данных | E21: Уровень сложности проекта | F21: =IF(F8="","",F8) -> х | G21: =IF(G8="","",G8) | H21: =IF(H8="","",H8) | I21: =IFERROR(_xlfn.IFS($F21<>"",Настройки!$C$4,$G21<>"",Настройки!$D$4,$H21<>"",Настройки!$E$4)*S21,0) -> 1 | J21: =IFERROR(_xlfn.IFS($F21<>"",Настройки!$C$4,$G21<>"",Настройки!$D$4,$H21<>"",Настройки!$E$4)*T21,0) -> 1 | K21: =IFERROR(_xlfn.IFS($F21<>"",Настройки!$C$4,$G21<>"",Настройки!$D$4,$H21<>"",Настройки!$E$4)*U21,0) -> 0 | L21: =IFERROR(_xlfn.IFS($F21<>"",Настройки!$C$4,$G21<>"",Настройки!$D$4,$H21<>"",Настройки!$E$4)*V21,0) -> 3 | M21: =IFERROR(_xlfn.IFS($F21<>"",Настройки!$C$4,$G21<>"",Настройки!$D$4,$H21<>"",Настройки!$E$4)*W21,0) -> 1 | N21: =IFERROR(_xlfn.IFS($F21<>"",Настройки!$C$4,$G21<>"",Настройки!$D$4,$H21<>"",Настройки!$E$4)*X21,0) -> 1 | O21: =IFERROR(_xlfn.IFS($F21<>"",Настройки!$C$4,$G21<>"",Настройки!$D$4,$H21<>"",Настройки!$E$4)*Y21,0) -> 1 | P21: =IFERROR(_xlfn.IFS($F21<>"",Настройки!$C$4,$G21<>"",Настройки!$D$4,$H21<>"",Настройки!$E$4)*Z21,0) -> 0 | S21: 1 | T21: 1 | V21: 3 | W21: 1 | X21: 1 | Y21: 1
C22: 4. Разработка функции сбора (извлечения) | E22: Количество и сложность источников данных | F22: =F7 -> 1 | G22: =G7 -> 0 | H22: =H7 -> 0 | I22: =IFERROR((VLOOKUP(SUMPRODUCT($F$22:$H$22,Настройки!$C$13:$E$13),Настройки!$S:$T,2,0))*S22,0) -> 0.25 | J22: =IFERROR((VLOOKUP(SUMPRODUCT($F$22:$H$22,Настройки!$C$13:$E$13),Настройки!$S:$T,2,0))*T22,0) -> 1 | K22: =IFERROR((VLOOKUP(SUMPRODUCT($F$22:$H$22,Настройки!$C$13:$E$13),Настройки!$S:$T,2,0))*U22,0) -> 1 | L22: =IFERROR((VLOOKUP(SUMPRODUCT($F$22:$H$22,Настройки!$C$13:$E$13),Настройки!$S:$T,2,0))*V22,0) -> 0.5 | M22: =IFERROR((VLOOKUP(SUMPRODUCT($F$22:$H$22,Настройки!$C$13:$E$13),Настройки!$S:$T,2,0))*W22,0) -> 0 | N22: =IFERROR((VLOOKUP(SUMPRODUCT($F$22:$H$22,Настройки!$C$13:$E$13),Настройки!$S:$T,2,0))*X22,0) -> 1 | O22: =IFERROR((VLOOKUP(SUMPRODUCT($F$22:$H$22,Настройки!$C$13:$E$13),Настройки!$S:$T,2,0))*Y22,0) -> 0 | P22: =IFERROR((VLOOKUP(SUMPRODUCT($F$22:$H$22,Настройки!$C$13:$E$13),Настройки!$S:$T,2,0))*Z22,0) -> 0 | S22: 0.25 | T22: 1 | U22: 1 | V22: 0.5 | X22: 1
C23: 5. Очистка, подготовка и инженерия данных (инженерия, выявления аномалий, очистка, устранение ошибок и выбросов, заполнение пропущенных значений, стандартизаци и категоризация) данных для последующего моделирования
D24: a. Валидация табличных данных | E24: Определяется по количеству таблиц и их трудоёмкости. Указать уровень сложности. | F24: х | I24: =IFERROR(_xlfn.IFS($F24<>"",Настройки!$C$5,$G24<>"",Настройки!$D$5,$H24<>"",Настройки!$E$5)*S24,0) -> 0 | J24: =IFERROR(_xlfn.IFS($F24<>"",Настройки!$C$5,$G24<>"",Настройки!$D$5,$H24<>"",Настройки!$E$5)*T24,0) -> 5 | K24: =IFERROR(_xlfn.IFS($F24<>"",Настройки!$C$5,$G24<>"",Настройки!$D$5,$H24<>"",Настройки!$E$5)*U24,0) -> 5 | L24: =IFERROR(_xlfn.IFS($F24<>"",Настройки!$C$5,$G24<>"",Настройки!$D$5,$H24<>"",Настройки!$E$5)*V24,0) -> 0.5 | M24: =IFERROR(_xlfn.IFS($F24<>"",Настройки!$C$5,$G24<>"",Настройки!$D$5,$H24<>"",Настройки!$E$5)*W24,0) -> 0 | N24: =IFERROR(_xlfn.IFS($F24<>"",Настройки!$C$5,$G24<>"",Настройки!$D$5,$H24<>"",Настройки!$E$5)*X24,0) -> 5 | O24: =IFERROR(_xlfn.IFS($F24<>"",Настройки!$C$5,$G24<>"",Настройки!$D$5,$H24<>"",Настройки!$E$5)*Y24,0) -> 0 | P24: =IFERROR(_xlfn.IFS($F24<>"",Настройки!$C$5,$G24<>"",Настройки!$D$5,$H24<>"",Настройки!$E$5)*Z24,0) -> 0 | T24: 5 | U24: 5 | V24: 0.5 | X24: 5
D25: b. Валидация неструктурированных данных: Фото и видео материал, звуковые дорожки | E25: Определяется по объёму и разрешению, ширине видеопотока (битрейт), FPS, глубине цвета, скорости обработки видео. Указать уровень сложности. | F25: х | I25: =IFERROR(_xlfn.IFS($F25<>"",Настройки!$C$6,$G25<>"",Настройки!$D$6,$H25<>"",Настройки!$E$6)*S25,0) -> 0 | J25: =IFERROR(_xlfn.IFS($F25<>"",Настройки!$C$6,$G25<>"",Настройки!$D$6,$H25<>"",Настройки!$E$6)*T25,0) -> 5 | K25: =IFERROR(_xlfn.IFS($F25<>"",Настройки!$C$6,$G25<>"",Настройки!$D$6,$H25<>"",Настройки!$E$6)*U25,0) -> 5 | L25: =IFERROR(_xlfn.IFS($F25<>"",Настройки!$C$6,$G25<>"",Настройки!$D$6,$H25<>"",Настройки!$E$6)*V25,0) -> 0.5 | M25: =IFERROR(_xlfn.IFS($F25<>"",Настройки!$C$6,$G25<>"",Настройки!$D$6,$H25<>"",Настройки!$E$6)*W25,0) -> 0 | N25: =IFERROR(_xlfn.IFS($F25<>"",Настройки!$C$6,$G25<>"",Настройки!$D$6,$H25<>"",Настройки!$E$6)*X25,0) -> 5 | O25: =IFERROR(_xlfn.IFS($F25<>"",Настройки!$C$6,$G25<>"",Настройки!$D$6,$H25<>"",Настройки!$E$6)*Y25,0) -> 0 | P25: =IFERROR(_xlfn.IFS($F25<>"",Настройки!$C$6,$G25<>"",Настройки!$D$6,$H25<>"",Настройки!$E$6)*Z25,0) -> 0 | T25: 5 | U25: 5 | V25: 0.5 | X25: 5
D26: c. Валидация временных рядов: телеметрия | E26: Уровень сложности определяется по количеству тегов телеметрии и плотности сигнала. Указать уровень сложности. | F26: х | I26: =IFERROR(_xlfn.IFS($F26<>"",Настройки!$C$7,$G26<>"",Настройки!$D$7,$H26<>"",Настройки!$E$7)*S26,0) -> 0 | J26: =IFERROR(_xlfn.IFS($F26<>"",Настройки!$C$7,$G26<>"",Настройки!$D$7,$H26<>"",Настройки!$E$7)*T26,0) -> 3 | K26: =IFERROR(_xlfn.IFS($F26<>"",Настройки!$C$7,$G26<>"",Настройки!$D$7,$H26<>"",Настройки!$E$7)*U26,0) -> 3 | L26: =IFERROR(_xlfn.IFS($F26<>"",Настройки!$C$7,$G26<>"",Настройки!$D$7,$H26<>"",Настройки!$E$7)*V26,0) -> 0.5 | M26: =IFERROR(_xlfn.IFS($F26<>"",Настройки!$C$7,$G26<>"",Настройки!$D$7,$H26<>"",Настройки!$E$7)*W26,0) -> 0 | N26: =IFERROR(_xlfn.IFS($F26<>"",Настройки!$C$7,$G26<>"",Настройки!$D$7,$H26<>"",Настройки!$E$7)*X26,0) -> 3 | O26: =IFERROR(_xlfn.IFS($F26<>"",Настройки!$C$7,$G26<>"",Настройки!$D$7,$H26<>"",Настройки!$E$7)*Y26,0) -> 0 | P26: =IFERROR(_xlfn.IFS($F26<>"",Настройки!$C$7,$G26<>"",Настройки!$D$7,$H26<>"",Настройки!$E$7)*Z26,0) -> 0 | T26: 3 | U26: 3 | V26: 0.5 | X26: 3
B27: Этап 3: Моделирование | I27: =SUM(I28:I30) -> 1 | J27: =SUM(J28:J30) -> 8 | K27: =SUM(K28:K30) -> 5 | L27: =SUM(L28:L30) -> 1 | M27: =SUM(M28:M30) -> 3 | N27: =SUM(N28:N30) -> 2 | O27: =SUM(O28:O30) -> 7 | P27: =SUM(P28:P30) -> 0 | Q27: Обученные модели, способные использовать данные для прогнозирования или классификации в соответствии с целями проекта. Результаты оценки производительности, включая точность, чувствительность и специфичность моделей, а также результаты тестирования на валидационных данных. Улучшенные гиперпараметры, наборы данных и настроенные параметры моделей для оптимизации их работы. Настроены WorkFlow процессы и модельные сервисы. | R27: Внутреннее заключение о готовности тестирования модели Описание модельного сервиса
C28: 6. Разработка и обучение моделей | E28: Количество и сложность модели | F28: =F9 -> 1 | G28: =G9 -> 0 | H28: =H9 -> 0 | I28: =IFERROR((VLOOKUP(SUMPRODUCT($F$28:$H$28,Настройки!$C$14:$E$14),Настройки!$X:$Y,2,0))*S28,0) -> 0.25 | J28: =IFERROR((VLOOKUP(SUMPRODUCT($F$28:$H$28,Настройки!$C$14:$E$14),Настройки!$X:$Y,2,0))*T28,0) -> 3 | K28: =IFERROR((VLOOKUP(SUMPRODUCT($F$28:$H$28,Настройки!$C$14:$E$14),Настройки!$X:$Y,2,0))*U28,0) -> 3 | L28: =IFERROR((VLOOKUP(SUMPRODUCT($F$28:$H$28,Настройки!$C$14:$E$14),Настройки!$X:$Y,2,0))*V28,0) -> 0 | M28: =IFERROR((VLOOKUP(SUMPRODUCT($F$28:$H$28,Настройки!$C$14:$E$14),Настройки!$X:$Y,2,0))*W28,0) -> 3 | N28: =IFERROR((VLOOKUP(SUMPRODUCT($F$28:$H$28,Настройки!$C$14:$E$14),Настройки!$X:$Y,2,0))*X28,0) -> 2 | O28: =IFERROR((VLOOKUP(SUMPRODUCT($F$28:$H$28,Настройки!$C$14:$E$14),Настройки!$X:$Y,2,0))*Y28,0) -> 0 | P28: =IFERROR((VLOOKUP(SUMPRODUCT($F$28:$H$28,Настройки!$C$14:$E$14),Настройки!$X:$Y,2,0))*Z28,0) -> 0 | S28: 0.25 | T28: 3 | U28: 3 | W28: 3 | X28: 2
C29: 7. Операционализация моделей | E29: Количество и сложность модели | F29: =F9 -> 1 | G29: =G9 -> 0 | H29: =H9 -> 0 | I29: =IFERROR((VLOOKUP(SUMPRODUCT($F$29:$H$29,Настройки!$C$15:$E$15),Настройки!$AC:$AD,2,0))*S29,0) -> 0.25 | J29: =IFERROR((VLOOKUP(SUMPRODUCT($F$29:$H$29,Настройки!$C$15:$E$15),Настройки!$AC:$AD,2,0))*T29,0) -> 3 | K29: =IFERROR((VLOOKUP(SUMPRODUCT($F$29:$H$29,Настройки!$C$15:$E$15),Настройки!$AC:$AD,2,0))*U29,0) -> 0 | L29: =IFERROR((VLOOKUP(SUMPRODUCT($F$29:$H$29,Настройки!$C$15:$E$15),Настройки!$AC:$AD,2,0))*V29,0) -> 0.5 | M29: =IFERROR((VLOOKUP(SUMPRODUCT($F$29:$H$29,Настройки!$C$15:$E$15),Настройки!$AC:$AD,2,0))*W29,0) -> 0 | N29: =IFERROR((VLOOKUP(SUMPRODUCT($F$29:$H$29,Настройки!$C$15:$E$15),Настройки!$AC:$AD,2,0))*X29,0) -> 0 | O29: =IFERROR((VLOOKUP(SUMPRODUCT($F$29:$H$29,Настройки!$C$15:$E$15),Настройки!$AC:$AD,2,0))*Y29,0) -> 5 | P29: =IFERROR((VLOOKUP(SUMPRODUCT($F$29:$H$29,Настройки!$C$15:$E$15),Настройки!$AC:$AD,2,0))*Z29,0) -> 0 | S29: 0.25 | T29: 3 | V29: 0.5 | Y29: 5
C30: 8. Оценка производительности и тестирование моделей (отладка) | E30: Количество и сложность модели | F30: =F9 -> 1 | G30: =G9 -> 0 | H30: =H9 -> 0 | I30: =IFERROR((VLOOKUP(SUMPRODUCT($F$30:$H$30,Настройки!$C$16:$E$16),Настройки!$AH:$AI,2,0))*S30,0) -> 0.5 | J30: =IFERROR((VLOOKUP(SUMPRODUCT($F$30:$H$30,Настройки!$C$16:$E$16),Настройки!$AH:$AI,2,0))*T30,0) -> 2 | K30: =IFERROR((VLOOKUP(SUMPRODUCT($F$30:$H$30,Настройки!$C$16:$E$16),Настройки!$AH:$AI,2,0))*U30,0) -> 2 | L30: =IFERROR((VLOOKUP(SUMPRODUCT($F$30:$H$30,Настройки!$C$16:$E$16),Настройки!$AH:$AI,2,0))*V30,0) -> 0.5 | M30: =IFERROR((VLOOKUP(SUMPRODUCT($F$30:$H$30,Настройки!$C$16:$E$16),Настройки!$AH:$AI,2,0))*W30,0) -> 0 | N30: =IFERROR((VLOOKUP(SUMPRODUCT($F$30:$H$30,Настройки!$C$16:$E$16),Настройки!$AH:$AI,2,0))*X30,0) -> 0 | O30: =IFERROR((VLOOKUP(SUMPRODUCT($F$30:$H$30,Настройки!$C$16:$E$16),Настройки!$AH:$AI,2,0))*Y30,0) -> 2 | P30: =IFERROR((VLOOKUP(SUMPRODUCT($F$30:$H$30,Настройки!$C$16:$E$16),Настройки!$AH:$AI,2,0))*Z30,0) -> 0 | S30: 0.5 | T30: 2 | U30: 2 | V30: 0.5 | Y30: 2
B31: Этап 4: Пуско-наладочные испытания и оптимизация | I31: =SUM(I32:I34) -> 3.1 | J31: =SUM(J32:J34) -> 3.25 | K31: =SUM(K32:K34) -> 4 | L31: =SUM(L32:L34) -> 3.1 | M31: =SUM(M32:M34) -> 3.1 | N31: =SUM(N32:N34) -> 0 | O31: =SUM(O32:O34) -> 2.1 | P31: =SUM(P32:P34) -> 0 | Q31: Программа ПСИ. Проведены тестовые пуско-наладочные испытания. Проведен анализ производительности и эффективности обученных моделей. Измерение скорости работы системы. Метрики производительности и оценка стабильности. Выявлены недостатки моделей ML. Корректировка параметров системы и моделей для достижения оптимальных результатов. Улучшена производительность и эффективность работы системы в рамках SLA. Протокол испытаний с реестром замечаний. | R31: Сценарий тестирования Протокол тестирования Реестр ошибок тестирования
C32: 9. Функционально и/или интеграционное тестирование. Описать этапы тестирования, испытаний и сдача работ. | E32: WorkFlow процессы. Указать уровень сложности. | F32: Х | I32: =IFERROR(_xlfn.IFS($F32<>"",Настройки!$C$8,$G32<>"",Настройки!$D$8,$H32<>"",Настройки!$E$8)*S32,0) -> 2 | J32: =IFERROR(_xlfn.IFS($F32<>"",Настройки!$C$8,$G32<>"",Настройки!$D$8,$H32<>"",Настройки!$E$8)*T32,0) -> 2 | K32: =IFERROR(_xlfn.IFS($F32<>"",Настройки!$C$8,$G32<>"",Настройки!$D$8,$H32<>"",Настройки!$E$8)*U32,0) -> 2 | L32: =IFERROR(_xlfn.IFS($F32<>"",Настройки!$C$8,$G32<>"",Настройки!$D$8,$H32<>"",Настройки!$E$8)*V32,0) -> 2 | M32: =IFERROR(_xlfn.IFS($F32<>"",Настройки!$C$8,$G32<>"",Настройки!$D$8,$H32<>"",Настройки!$E$8)*W32,0) -> 2 | N32: =IFERROR(_xlfn.IFS($F32<>"",Настройки!$C$8,$G32<>"",Настройки!$D$8,$H32<>"",Настройки!$E$8)*X32,0) -> 0 | O32: =IFERROR(_xlfn.IFS($F32<>"",Настройки!$C$8,$G32<>"",Настройки!$D$8,$H32<>"",Настройки!$E$8)*Y32,0) -> 1 | P32: =IFERROR(_xlfn.IFS($F32<>"",Настройки!$C$8,$G32<>"",Настройки!$D$8,$H32<>"",Настройки!$E$8)*Z32,0) -> 0 | S32: 2 | T32: 2 | U32: 2 | V32: 2 | W32: 2 | Y32: 1
C33: 10. Тестирование на предмет производительности и стабильности | E33: Количество дней тестирования | F33: 1 | I33: =IFERROR($F$33*S33,0) -> 0.1 | J33: =IFERROR($F$33*T33,0) -> 0.25 | K33: =IFERROR($F$33*U33,0) -> 1 | L33: =IFERROR($F$33*V33,0) -> 0.1 | M33: =IFERROR($F$33*W33,0) -> 0.1 | N33: =IFERROR($F$33*X33,0) -> 0 | O33: =IFERROR($F$33*Y33,0) -> 0.1 | P33: =IFERROR($F$33*Z33,0) -> 0 | S33: 0.1 | T33: 0.25 | U33: 1 | V33: 0.1 | W33: 0.1 | Y33: 0.1
C34: 11. Устранение выявленных замечаний, оптимизация и настройка модели ML | E34: WorkFlow процессы | F34: =F10 -> 1 | G34: =G10 -> 0 | H34: =H10 -> 0 | I34: =IFERROR((VLOOKUP(SUMPRODUCT($F$34:$H$34,Настройки!$C$17:$E$17),Настройки!$AM:$AN,2,0))*S34,0) -> 1 | J34: =IFERROR((VLOOKUP(SUMPRODUCT($F$34:$H$34,Настройки!$C$17:$E$17),Настройки!$AM:$AN,2,0))*T34,0) -> 1 | K34: =IFERROR((VLOOKUP(SUMPRODUCT($F$34:$H$34,Настройки!$C$17:$E$17),Настройки!$AM:$AN,2,0))*U34,0) -> 1 | L34: =IFERROR((VLOOKUP(SUMPRODUCT($F$34:$H$34,Настройки!$C$17:$E$17),Настройки!$AM:$AN,2,0))*V34,0) -> 1 | M34: =IFERROR((VLOOKUP(SUMPRODUCT($F$34:$H$34,Настройки!$C$17:$E$17),Настройки!$AM:$AN,2,0))*W34,0) -> 1 | N34: =IFERROR((VLOOKUP(SUMPRODUCT($F$34:$H$34,Настройки!$C$17:$E$17),Настройки!$AM:$AN,2,0))*X34,0) -> 0 | O34: =IFERROR((VLOOKUP(SUMPRODUCT($F$34:$H$34,Настройки!$C$17:$E$17),Настройки!$AM:$AN,2,0))*Y34,0) -> 1 | P34: =IFERROR((VLOOKUP(SUMPRODUCT($F$34:$H$34,Настройки!$C$17:$E$17),Настройки!$AM:$AN,2,0))*Z34,0) -> 0 | S34: 1 | T34: 1 | U34: 1 | V34: 1 | W34: 1 | Y34: 1
B35: Этап 5: Обучение и Документация | I35: =SUM(I36:I38) -> 2 | J35: =SUM(J36:J38) -> 1.25 | K35: =SUM(K36:K38) -> 3 | L35: =SUM(L36:L38) -> 0.25 | M35: =SUM(M36:M38) -> 0.25 | N35: =SUM(N36:N38) -> 0.25 | O35: =SUM(O36:O38) -> 1.75 | P35: =SUM(P36:P38) -> 1.5 | Q35: План и программа обучения. Материалы обучения. Написаны пользовательских инструкций и руководств по развертыванию, которые описывают, как использовать систему. Обучение заказчика, включая проведение тренингов и семинаров, согласно программе обучения. Документирование проекта в соответствии с договором и этапами. | R35: Пользовательские инструкции
C36: 12. Написание пользовательских инструкций и инструкций по развертыванию | E36: WorkFlow процессы | F36: =F10 -> 1 | G36: =G10 -> 0 | H36: =H10 -> 0 | I36: =IFERROR((VLOOKUP(SUMPRODUCT($F$36:$H$36,Настройки!$C$18:$E$18),Настройки!$AR:$AS,2,0))*S36,0) -> 0 | J36: =IFERROR((VLOOKUP(SUMPRODUCT($F$36:$H$36,Настройки!$C$18:$E$18),Настройки!$AR:$AS,2,0))*T36,0) -> 0.25 | K36: =IFERROR((VLOOKUP(SUMPRODUCT($F$36:$H$36,Настройки!$C$18:$E$18),Настройки!$AR:$AS,2,0))*U36,0) -> 1 | L36: =IFERROR((VLOOKUP(SUMPRODUCT($F$36:$H$36,Настройки!$C$18:$E$18),Настройки!$AR:$AS,2,0))*V36,0) -> 0 | M36: =IFERROR((VLOOKUP(SUMPRODUCT($F$36:$H$36,Настройки!$C$18:$E$18),Настройки!$AR:$AS,2,0))*W36,0) -> 0 | N36: =IFERROR((VLOOKUP(SUMPRODUCT($F$36:$H$36,Настройки!$C$18:$E$18),Настройки!$AR:$AS,2,0))*X36,0) -> 0 | O36: =IFERROR((VLOOKUP(SUMPRODUCT($F$36:$H$36,Настройки!$C$18:$E$18),Настройки!$AR:$AS,2,0))*Y36,0) -> 0.25 | P36: =IFERROR((VLOOKUP(SUMPRODUCT($F$36:$H$36,Настройки!$C$18:$E$18),Настройки!$AR:$AS,2,0))*Z36,0) -> 0.25 | T36: 0.25 | U36: 1 | Y36: 0.25 | Z36: 0.25
C37: 13. Подготовка и обучение заказчика | E37: WorkFlow процессы | F37: =F10 -> 1 | G37: =G10 -> 0 | H37: =H10 -> 0 | I37: =IFERROR((VLOOKUP(SUMPRODUCT($F$37:$H$37,Настройки!$C$19:$E$19),Настройки!$AX:$AY,2,0))*S37,0) -> 1 | J37: =IFERROR((VLOOKUP(SUMPRODUCT($F$37:$H$37,Настройки!$C$19:$E$19),Настройки!$AX:$AY,2,0))*T37,0) -> 0 | K37: =IFERROR((VLOOKUP(SUMPRODUCT($F$37:$H$37,Настройки!$C$19:$E$19),Настройки!$AX:$AY,2,0))*U37,0) -> 1 | L37: =IFERROR((VLOOKUP(SUMPRODUCT($F$37:$H$37,Настройки!$C$19:$E$19),Настройки!$AX:$AY,2,0))*V37,0) -> 0 | M37: =IFERROR((VLOOKUP(SUMPRODUCT($F$37:$H$37,Настройки!$C$19:$E$19),Настройки!$AX:$AY,2,0))*W37,0) -> 0 | N37: =IFERROR((VLOOKUP(SUMPRODUCT($F$37:$H$37,Настройки!$C$19:$E$19),Настройки!$AX:$AY,2,0))*X37,0) -> 0 | O37: =IFERROR((VLOOKUP(SUMPRODUCT($F$37:$H$37,Настройки!$C$19:$E$19),Настройки!$AX:$AY,2,0))*Y37,0) -> 1 | P37: =IFERROR((VLOOKUP(SUMPRODUCT($F$37:$H$37,Настройки!$C$19:$E$19),Настройки!$AX:$AY,2,0))*Z37,0) -> 1 | S37: 1 | U37: 1 | Y37: 1 | Z37: 1
C38: 14. Документирование проекта | E38: Уровень сложности проекта | F38: =IF(F8="","",F8) -> х | G38: =IF(G8="","",G8) | H38: =IF(H8="","",H8) | I38: =IFERROR(_xlfn.IFS($F38<>"",Настройки!$C$9,$G38<>"",Настройки!$D$9,$H38<>"",Настройки!$E$9)*S38,0) -> 1 | J38: =IFERROR(_xlfn.IFS($F38<>"",Настройки!$C$9,$G38<>"",Настройки!$D$9,$H38<>"",Настройки!$E$9)*T38,0) -> 1 | K38: =IFERROR(_xlfn.IFS($F38<>"",Настройки!$C$9,$G38<>"",Настройки!$D$9,$H38<>"",Настройки!$E$9)*U38,0) -> 1 | L38: =IFERROR(_xlfn.IFS($F38<>"",Настройки!$C$9,$G38<>"",Настройки!$D$9,$H38<>"",Настройки!$E$9)*V38,0) -> 0.25 | M38: =IFERROR(_xlfn.IFS($F38<>"",Настройки!$C$9,$G38<>"",Настройки!$D$9,$H38<>"",Настройки!$E$9)*W38,0) -> 0.25 | N38: =IFERROR(_xlfn.IFS($F38<>"",Настройки!$C$9,$G38<>"",Настройки!$D$9,$H38<>"",Настройки!$E$9)*X38,0) -> 0.25 | O38: =IFERROR(_xlfn.IFS($F38<>"",Настройки!$C$9,$G38<>"",Настройки!$D$9,$H38<>"",Настройки!$E$9)*Y38,0) -> 0.5 | P38: =IFERROR(_xlfn.IFS($F38<>"",Настройки!$C$9,$G38<>"",Настройки!$D$9,$H38<>"",Настройки!$E$9)*Z38,0) -> 0.25 | R38: Руководство администратора | S38: 1 | T38: 1 | U38: 1 | V38: 0.25 | W38: 0.25 | X38: 0.25 | Y38: 0.5 | Z38: 0.25
B39: Этап 6: Завершение проекта | I39: =SUM(I40:I42) -> 2.63 | J39: =SUM(J40:J42) -> 2.725 | K39: =SUM(K40:K42) -> 1.575 | L39: =SUM(L40:L42) -> 0.63 | M39: =SUM(M40:M42) -> 0.68 | N39: =SUM(N40:N42) -> 0.8625 | O39: =SUM(O40:O42) -> 0.5925 | P39: =SUM(P40:P42) -> 1.4 | Q39: Дана оценка и анализ результатов, включая сравнение фактических результатов с исходными целями и задачами проекта. Проекта передан заказчику, включая передачу всех документации согласно договору и этапов проекта. Протокол закрытия проекта. | R39: Протокол сдачи проекта
C40: 15. Оценка и анализ результатов | E40: Определяется по KPI. Указать уровень сложности. | F40: х | I40: =IFERROR(_xlfn.IFS($F40<>"",Настройки!$C$10,$G40<>"",Настройки!$D$10,$H40<>"",Настройки!$E$10)*S40,0) -> 1 | J40: =IFERROR(_xlfn.IFS($F40<>"",Настройки!$C$10,$G40<>"",Настройки!$D$10,$H40<>"",Настройки!$E$10)*T40,0) -> 1 | K40: =IFERROR(_xlfn.IFS($F40<>"",Настройки!$C$10,$G40<>"",Настройки!$D$10,$H40<>"",Настройки!$E$10)*U40,0) -> 0 | L40: =IFERROR(_xlfn.IFS($F40<>"",Настройки!$C$10,$G40<>"",Настройки!$D$10,$H40<>"",Настройки!$E$10)*V40,0) -> 0 | M40: =IFERROR(_xlfn.IFS($F40<>"",Настройки!$C$10,$G40<>"",Настройки!$D$10,$H40<>"",Настройки!$E$10)*W40,0) -> 0.25 | N40: =IFERROR(_xlfn.IFS($F40<>"",Настройки!$C$10,$G40<>"",Настройки!$D$10,$H40<>"",Настройки!$E$10)*X40,0) -> 0 | O40: =IFERROR(_xlfn.IFS($F40<>"",Настройки!$C$10,$G40<>"",Настройки!$D$10,$H40<>"",Настройки!$E$10)*Y40,0) -> 0 | P40: =IFERROR(_xlfn.IFS($F40<>"",Настройки!$C$10,$G40<>"",Настройки!$D$10,$H40<>"",Настройки!$E$10)*Z40,0) -> 1 | S40: 1 | T40: 1 | W40: 0.25 | Z40: 1
...

Sheet Настройки
C1: Норматив | H1: 1. Оценка времени на исследование и анализ | M1: 2. Определение источников данных в инфраструктуре и внешних источниках | R1: 4. Разработка функции сбора (извлечения) | W1: 6. Разработка и обучение моделей | AB1: 7. Операционализация моделей | AG1: 8. Оценка производительности и тестирование моделей | AL1: 11. Оптимизация и настройка | AQ1: 12. Написание пользовательских инструкций и инструкций по развертыванию | AW1: 13. Обучение заказчика
C2: Простой | D2: Средний | E2: Сложный | I2: Балы | J2: Коэф. | K2: Огранич | N2: Балы | O2: Коэф. | P2: Огранич | S2: Балы | T2: Коэф. | U2: >1 простых Х1 | X2: Балы | Y2: Коэф. | Z2: >1 простых Х1; 2 простых х1,3 | AC2: Балы | AD2: Коэф. | AE2: >1 простых Х1; 2 простых х1,3 | AH2: Балы | AI2: Коэф. | AM2: Балы | AN2: Коэф. | AR2: Балы | AS2: Коэф. | AT2: >1 простых Х1, 2 простых х1,3 | AX2: Балы | AY2: Коэф.
B3: 1. Оценка времени на исследование и анализ. Бизнес домен | C3: 1 | D3: 3 | E3: 7 | H3: Простой | I3: 1 | J3: 1 | K3: Сложный | M3: Простой | N3: 1 | O3: 1 | P3: Сложный | R3: Простой | S3: 1 | T3: 1 | U3: >=10 сложных это х20 | W3: Простой | X3: 1 | Y3: 1 | Z3: 1 средняя х2 | AB3: Простой | AC3: 1 | AD3: 1 | AE3: 1 средняя х2 | AG3: Простой | AH3: 1 | AI3: 1 | AL3: Простой | AM3: 1 | AN3: 1 | AQ3: Простой | AR3: 1 | AS3: 1 | AT3: 1 средняя х2 | AW3: Простой | AX3: 1 | AY3: 1
A4: Уровень сложности | B4: 3. Разработка стратегии сбора данных | C4: 1 | D4: 2.5 | E4: 3.3 | H4: Простой | I4: 2 | J4: 1.5 | M4: Простой | N4: 2 | O4: 1 | P4: >3 простых Х1 | R4: Простой | S4: 2 | T4: 1 | W4: Простой | X4: 2 | Y4: =Y3+1/3 -> 1.3333333 | Z4: 1 сложная х4,3 | AB4: Простой | AC4: 2 | AD4: =AD3+1/3 -> 1.3333333 | AE4: 1 сложная х4,3 | AG4: Простой | AH4: 2 | AI4: =AI3+1/3 -> 1.3333333 | AL4: Простой | AM4: 2 | AN4: =AN3+1/3 -> 1.3333333 | AQ4: Простой | AR4: 2 | AS4: =AS3+1/3 -> 1.3333333 | AT4: 1 сложная х10 | AW4: Простой | AX4: 2 | AY4: =AY3+1/3 -> 1.3333333
A5: Уровень сложности | B5: a. Валидация табличных данных | C5: 1 | D5: 2.5 | E5: 3.3 | H5: Средний | I5: 3 | J5: 2 | M5: Простой | N5: 3 | O5: 1 | P5: >=10 сложных это х20 | R5: Простой | S5: 3 | T5: 1 | W5: Простой | X5: 3 | Y5: =Y4+1/3 -> 1.6666667 | AB5: Простой | AC5: 3 | AD5: =AD4+1/3 -> 1.6666667 | AG5: Простой | AH5: 3 | AI5: =AI4+1/3 -> 1.6666667 | AL5: Простой | AM5: 3 | AN5: =AN4+1/3 -> 1.6666667 | AQ5: Простой | AR5: 3 | AS5: =AS4+1/3 -> 1.6666667 | AW5: Простой | AX5: 3 | AY5: =AY4+1/3 -> 1.6666667
A6: Уровень сложности | B6: b. Валидация неструктурированных данных: Фото и видео материал, звуковые дорожки | C6: 1 | D6: 2.5 | E6: 3.3 | H6: Средний | I6: 4 | J6: 2.25 | M6: Средний | N6: 4 | O6: 1.5 | R6: Средний | S6: 4 | T6: 1.5 | W6: Средний | X6: 4 | Y6: =Y5+1/3 -> 2 | AB6: Средний | AC6: 4 | AD6: =AD5+1/3 -> 2 | AG6: Средний | AH6: 4 | AI6: =AI5+1/3 -> 2 | AL6: Средний | AM6: 4 | AN6: =AN5+1/3 -> 2 | AQ6: Средний | AR6: 4 | AS6: =AS5+1/3 -> 2 | AW6: Средний | AX6: 4 | AY6: =AY5+1/3 -> 2
A7: Уровень сложности | B7: c. Валидация временных рядов: телеметрия | C7: 1 | D7: 2.5 | E7: 3.3 | H7: Средний | I7: 5 | J7: 2.5 | M7: Средний | N7: 5 | O7: 1.5 | R7: Средний | S7: 5 | T7: 1.5 | W7: Средний | X7: 5 | Y7: =Y6+1/3 -> 2.3333333 | AB7: Средний | AC7: 5 | AD7: =AD6+1/3 -> 2.3333333 | AG7: Средний | AH7: 5 | AI7: =AI6+1/3 -> 2.3333333 | AL7: Средний | AM7: 5 | AN7: =AN6+1/3 -> 2.3333333 | AQ7: Средний | AR7: 5 | AS7: =AS6+1/3 -> 2.3333333 | AW7: Средний | AX7: 5 | AY7: =AY6+1/3 -> 2.3333333
A8: Уровень сложности | B8: 9. Функционально и/или интеграционное тестирование. Описать этапы тестирования, испытаний и сдача работ. | C8: 1 | D8: 3 | E8: 5 | H8: Средний | I8: 6 | J8: 2.75 | M8: Средний | N8: 6 | O8: 1.5 | R8: Средний | S8: 6 | T8: 1.5 | W8: Средний | X8: 6 | Y8: =Y7+1/3 -> 2.6666667 | AB8: Средний | AC8: 6 | AD8: =AD7+1/3 -> 2.6666667 | AG8: Средний | AH8: 6 | AI8: =AI7+1/3 -> 2.6666667 | AL8: Средний | AM8: 6 | AN8: =AN7+1/3 -> 2.6666667 | AQ8: Средний | AR8: 6 | AS8: =AS7+1/3 -> 2.6666667 | AW8: Средний | AX8: 6 | AY8: =AY7+1/3 -> 2.6666667
A9: Уровень сложности | B9: 14. Документирование проекта | C9: 1 | D9: 2 | E9: 3 | H9: Сложный | I9: 7 | J9: 3 | M9: Средний | N9: 7 | O9: 1.5 | R9: Средний | S9: 7 | T9: 1.5 | W9: Средний | X9: 7 | Y9: =Y8+1/3 -> 3 | AB9: Средний | AC9: 7 | AD9: =AD8+1/3 -> 3 | AG9: Средний | AH9: 7 | AI9: =AI8+1/3 -> 3 | AL9: Средний | AM9: 7 | AN9: =AN8+1/3 -> 3 | AQ9: Средний | AR9: 7 | AS9: =AS8+1/3 -> 3 | AW9: Средний | AX9: 7 | AY9: =AY8+1/3 -> 3
A10: Уровень сложности | B10: 15. Оценка и анализ результатов | C10: 1 | D10: 5 | E10: 10 | H10: Сложный | I10: 8 | J10: 3 | M10: Средний | N10: 8 | O10: 1.5 | R10: Средний | S10: 8 | T10: 1.5 | W10: Средний | X10: 8 | Y10: =Y9+1/3 -> 3.3333333 | AB10: Средний | AC10: 8 | AD10: =AD9+1/3 -> 3.3333333 | AG10: Средний | AH10: 8 | AI10: =AI9+1/3 -> 3.3333333 | AL10: Средний | AM10: 8 | AN10: =AN9+1/3 -> 3.3333333 | AQ10: Средний | AR10: 8 | AS10: =AS9+1/3 -> 3.3333333 | AW10: Средний | AX10: 8 | AY10: =AY9+1/3 -> 3.3333333
A11: Уровень сложности | B11: 16. Передача проекта заказчику | C11: 1 | D11: 2 | E11: 3 | H11: Сложный | I11: 9 | J11: 3 | M11: Сложный | N11: 9 | O11: 2 | R11: Сложный | S11: 9 | T11: 2 | W11: Средний | X11: 9 | Y11: =Y10+1/3 -> 3.6666667 | AB11: Средний | AC11: 9 | AD11: =AD10+1/3 -> 3.6666667 | AG11: Средний | AH11: 9 | AI11: =AI10+1/3 -> 3.6666667 | AL11: Средний | AM11: 9 | AN11: =AN10+1/3 -> 3.6666667 | AQ11: Средний | AR11: 9 | AS11: =AS10+1/3 -> 3.6666667 | AW11: Средний | AX11: 9 | AY11: =AY10+1/3 -> 3.6666667
A12: Количество в разрезе их сложности | B12: 2. Определение источников данных в инфраструктуре и внешних источниках | C12: 1 | D12: 4 | E12: 9 | H12: Сложный | I12: 10 | J12: 3 | M12: Сложный | N12: 10 | O12: 2 | R12: Сложный | S12: 10 | T12: 2 | W12: Средний | X12: 10 | Y12: =Y11+1/3 -> 4 | AB12: Средний | AC12: 10 | AD12: =AD11+1/3 -> 4 | AG12: Средний | AH12: 10 | AI12: =AI11+1/3 -> 4 | AL12: Средний | AM12: 10 | AN12: =AN11+1/3 -> 4 | AQ12: Средний | AR12: 10 | AS12: =AS11+1/3 -> 4 | AW12: Средний | AX12: 10 | AY12: =AY11+1/3 -> 4
A13: Количество в разрезе их сложности | B13: 4. Разработка функции сбора (извлечения) | C13: 1 | D13: 4 | E13: 9 | H13: Сложный | I13: 11 | J13: 3 | M13: Сложный | N13: 11 | O13: 2 | R13: Сложный | S13: 11 | T13: 2 | W13: Сложный | X13: 11 | Y13: =Y12+1/3 -> 4.3333333 | AB13: Сложный | AC13: 11 | AD13: =AD12+1/3 -> 4.3333333 | AG13: Сложный | AH13: 11 | AI13: =AI12+1/3 -> 4.3333333 | AL13: Сложный | AM13: 11 | AN13: =AN12+1/3 -> 4.3333333 | AQ13: Сложный | AR13: 11 | AS13: =AS12+1/3 -> 4.3333333 | AW13: Сложный | AX13: 11 | AY13: =AY12+1/3 -> 4.3333333
A14: Количество в разрезе их сложности | B14: 6. Разработка и обучение моделей | C14: 1 | D14: 4 | E14: 11 | H14: Сложный | I14: 12 | J14: 3 | M14: Сложный | N14: 12 | O14: 2 | R14: Сложный | S14: 12 | T14: 2 | W14: Сложный | X14: 12 | Y14: =Y13+1/3 -> 4.6666667 | AB14: Сложный | AC14: 12 | AD14: =AD13+1/3 -> 4.6666667 | AG14: Сложный | AH14: 12 | AI14: =AI13+1/3 -> 4.6666667 | AL14: Сложный | AM14: 12 | AN14: =AN13+1/3 -> 4.6666667 | AQ14: Сложный | AR14: 12 | AS14: =AS13+1/3 -> 4.6666667 | AW14: Сложный | AX14: 12 | AY14: =AY13+1/3 -> 4.6666667
A15: Количество в разрезе их сложности | B15: 7. Операционализация моделей | C15: 1 | D15: 4 | E15: 11 | H15: Сложный | I15: 13 | J15: 3 | M15: Сложный | N15: 13 | O15: 2 | R15: Сложный | S15: 13 | T15: 2 | W15: Сложный | X15: 13 | Y15: =Y14+1/3 -> 5 | AB15: Сложный | AC15: 13 | AD15: =AD14+1/3 -> 5 | AG15: Сложный | AH15: 13 | AI15: =AI14+1/3 -> 5 | AL15: Сложный | AM15: 13 | AN15: =AN14+1/3 -> 5 | AQ15: Сложный | AR15: 13 | AS15: =AS14+1/3 -> 5 | AW15: Сложный | AX15: 13 | AY15: =AY14+1/3 -> 5
A16: Количество в разрезе их сложности | B16: 8. Оценка производительности и тестирование моделей | C16: 1 | D16: 4 | E16: 11 | H16: Сложный | I16: 14 | J16: 3 | M16: Сложный | N16: 14 | O16: 2 | R16: Сложный | S16: 14 | T16: 2 | W16: Сложный | X16: 14 | Y16: =Y15+1/3 -> 5.3333333 | AB16: Сложный | AC16: 14 | AD16: =AD15+1/3 -> 5.3333333 | AG16: Сложный | AH16: 14 | AI16: =AI15+1/3 -> 5.3333333 | AL16: Сложный | AM16: 14 | AN16: =AN15+1/3 -> 5.3333333 | AQ16: Сложный | AR16: 14 | AS16: =AS15+1/3 -> 5.3333333 | AW16: Сложный | AX16: 14 | AY16: =AY15+1/3 -> 5.3333333
A17: Количество в разрезе их сложности | B17: 11. Оптимизация и настройка | C17: 1 | D17: 4 | E17: 11 | M17: Сложный | N17: 15 | O17: 2 | R17: Сложный | S17: 15 | T17: 2 | W17: Сложный | X17: 15 | Y17: =Y16+1/3 -> 5.6666667 | AB17: Сложный | AC17: 15 | AD17: =AD16+1/3 -> 5.6666667 | AG17: Сложный | AH17: 15 | AI17: =AI16+1/3 -> 5.6666667 | AL17: Сложный | AM17: 15 | AN17: =AN16+1/3 -> 5.6666667 | AQ17: Сложный | AR17: 15 | AS17: =AS16+1/3 -> 5.6666667 | AW17: Сложный | AX17: 15 | AY17: =AY16+1/3 -> 5.6666667
A18: Количество в разрезе их сложности | B18: 12. Написание пользовательских инструкций и инструкций по развертыванию | C18: 1 | D18: 4 | E18: 11 | M18: Сложный | N18: 16 | O18: 2 | R18: Сложный | S18: 16 | T18: 2 | W18: Сложный | X18: 16 | Y18: =Y17+1/3 -> 6 | AB18: Сложный | AC18: 16 | AD18: =AD17+1/3 -> 6 | AG18: Сложный | AH18: 16 | AI18: =AI17+1/3 -> 6 | AL18: Сложный | AM18: 16 | AN18: =AN17+1/3 -> 6 | AQ18: Сложный | AR18: 16 | AS18: =AS17+1/3 -> 6 | AW18: Сложный | AX18: 16 | AY18: =AY17+1/3 -> 6
A19: Количество в разрезе их сложности | B19: 13. Обучение заказчика | C19: 1 | D19: 4 | E19: 11 | M19: Сложный | N19: 17 | O19: 2 | R19: Сложный | S19: 17 | T19: 2 | W19: Сложный | X19: 17 | Y19: =Y18+1/3 -> 6.3333333 | AB19: Сложный | AC19: 17 | AD19: =AD18+1/3 -> 6.3333333 | AG19: Сложный | AH19: 17 | AI19: =AI18+1/3 -> 6.3333333 | AL19: Сложный | AM19: 17 | AN19: =AN18+1/3 -> 6.3333333 | AQ19: Сложный | AR19: 17 | AS19: =AS18+1/3 -> 6.3333333 | AW19: Сложный | AX19: 17 | AY19: =AY18+1/3 -> 6.3333333
M20: Сложный | N20: 18 | O20: 3 | R20: Сложный | S20: 18 | T20: 3 | W20: Сложный | X20: 18 | Y20: =Y19+1/3 -> 6.6666667 | AB20: Сложный | AC20: 18 | AD20: =AD19+1/3 -> 6.6666667 | AG20: Сложный | AH20: 18 | AI20: =AI19+1/3 -> 6.6666667 | AL20: Сложный | AM20: 18 | AN20: =AN19+1/3 -> 6.6666667 | AQ20: Сложный | AR20: 18 | AS20: =AS19+1/3 -> 6.6666667 | AW20: Сложный | AX20: 18 | AY20: =AY19+1/3 -> 6.6666667
M21: Сложный | N21: 19 | O21: 3 | R21: Сложный | S21: 19 | T21: 3 | W21: Сложный | X21: 19 | Y21: =Y20+1/3 -> 7 | AB21: Сложный | AC21: 19 | AD21: =AD20+1/3 -> 7 | AG21: Сложный | AH21: 19 | AI21: =AI20+1/3 -> 7 | AL21: Сложный | AM21: 19 | AN21: =AN20+1/3 -> 7 | AQ21: Сложный | AR21: 19 | AS21: =AS20+1/3 -> 7 | AW21: Сложный | AX21: 19 | AY21: =AY20+1/3 -> 7
M22: Сложный | N22: 20 | O22: 3 | R22: Сложный | S22: 20 | T22: 3 | W22: Сложный | X22: 20 | Y22: =Y21+1/3 -> 7.3333333 | AB22: Сложный | AC22: 20 | AD22: =AD21+1/3 -> 7.3333333 | AG22: Сложный | AH22: 20 | AI22: =AI21+1/3 -> 7.3333333 | AL22: Сложный | AM22: 20 | AN22: =AN21+1/3 -> 7.3333333 | AQ22: Сложный | AR22: 20 | AS22: =AS21+1/3 -> 7.3333333 | AW22: Сложный | AX22: 20 | AY22: =AY21+1/3 -> 7.3333333
M23: Сложный | N23: 21 | O23: 3 | R23: Сложный | S23: 21 | T23: 3 | W23: Сложный | X23: 21 | Y23: =Y22+1/3 -> 7.6666667 | AB23: Сложный | AC23: 21 | AD23: =AD22+1/3 -> 7.6666667 | AG23: Сложный | AH23: 21 | AI23: =AI22+1/3 -> 7.6666667 | AL23: Сложный | AM23: 21 | AN23: =AN22+1/3 -> 7.6666667 | AQ23: Сложный | AR23: 21 | AS23: =AS22+1/3 -> 7.6666667 | AW23: Сложный | AX23: 21 | AY23: =AY22+1/3 -> 7.6666667
M24: Сложный | N24: 22 | O24: 3 | R24: Сложный | S24: 22 | T24: 3 | W24: Сложный | X24: 22 | Y24: =Y23+1/3 -> 8 | AB24: Сложный | AC24: 22 | AD24: =AD23+1/3 -> 8 | AG24: Сложный | AH24: 22 | AI24: =AI23+1/3 -> 8 | AL24: Сложный | AM24: 22 | AN24: =AN23+1/3 -> 8 | AQ24: Сложный | AR24: 22 | AS24: =AS23+1/3 -> 8 | AW24: Сложный | AX24: 22 | AY24: =AY23+1/3 -> 8
A25: Внутренние ставки по грейдам на 2024 | D25: Внешние ставки по грейдам на 2024 (Письмо от Рубановой от 22.03.24) | M25: Сложный | N25: 23 | O25: 3 | R25: Сложный | S25: 23 | T25: 3 | W25: Сложный | X25: 23 | Y25: =Y24+1/3 -> 8.3333333 | AB25: Сложный | AC25: 23 | AD25: =AD24+1/3 -> 8.3333333 | AG25: Сложный | AH25: 23 | AI25: =AI24+1/3 -> 8.3333333 | AL25: Сложный | AM25: 23 | AN25: =AN24+1/3 -> 8.3333333 | AQ25: Сложный | AR25: 23 | AS25: =AS24+1/3 -> 8.3333333 | AW25: Сложный | AX25: 23 | AY25: =AY24+1/3 -> 8.3333333
A26: Грейд | B26: ч/ч | C26: ч/д | D26: ч/ч | E26: ч/д | M26: Сложный | N26: 24 | O26: 3 | R26: Сложный | S26: 24 | T26: 3 | W26: Сложный | X26: 24 | Y26: =Y25+1/3 -> 8.6666667 | AB26: Сложный | AC26: 24 | AD26: =AD25+1/3 -> 8.6666667 | AG26: Сложный | AH26: 24 | AI26: =AI25+1/3 -> 8.6666667 | AL26: Сложный | AM26: 24 | AN26: =AN25+1/3 -> 8.6666667 | AQ26: Сложный | AR26: 24 | AS26: =AS25+1/3 -> 8.6666667 | AW26: Сложный | AX26: 24 | AY26: =AY25+1/3 -> 8.6666667
A27: К1 | B27: 1410 | C27: =B27*8 -> 11280 | D27: 1810 | E27: =D27*8 -> 14480 | M27: Сложный | N27: 25 | O27: 3 | R27: Сложный | S27: 25 | T27: 3 | W27: Сложный | X27: 25 | Y27: =Y26+1/3 -> 9 | AB27: Сложный | AC27: 25 | AD27: =AD26+1/3 -> 9 | AG27: Сложный | AH27: 25 | AI27: =AI26+1/3 -> 9 | AL27: Сложный | AM27: 25 | AN27: =AN26+1/3 -> 9 | AQ27: Сложный | AR27: 25 | AS27: =AS26+1/3 -> 9 | AW27: Сложный | AX27: 25 | AY27: =AY26+1/3 -> 9
A28: К2 | B28: 2160 | C28: =B28*8 -> 17280 | D28: 2890 | E28: =D28*8 -> 23120 | M28: Сложный | N28: 26 | O28: 3 | R28: Сложный | S28: 26 | T28: 3 | W28: Сложный | X28: 26 | Y28: =Y27+1/3 -> 9.3333333 | AB28: Сложный | AC28: 26 | AD28: =AD27+1/3 -> 9.3333333 | AG28: Сложный | AH28: 26 | AI28: =AI27+1/3 -> 9.3333333 | AL28: Сложный | AM28: 26 | AN28: =AN27+1/3 -> 9.3333333 | AQ28: Сложный | AR28: 26 | AS28: =AS27+1/3 -> 9.3333333 | AW28: Сложный | AX28: 26 | AY28: =AY27+1/3 -> 9.3333333
A29: К3 | B29: 2780 | C29: =B29*8 -> 22240 | D29: 3910 | E29: =D29*8 -> 31280 | M29: Сложный | N29: 27 | O29: 4 | R29: Сложный | S29: 27 | T29: 4 | W29: Сложный | X29: 27 | Y29: =Y28+1/3 -> 9.6666667 | AB29: Сложный | AC29: 27 | AD29: =AD28+1/3 -> 9.6666667 | AG29: Сложный | AH29: 27 | AI29: =AI28+1/3 -> 9.6666667 | AL29: Сложный | AM29: 27 | AN29: =AN28+1/3 -> 9.6666667 | AQ29: Сложный | AR29: 27 | AS29: =AS28+1/3 -> 9.6666667 | AW29: Сложный | AX29: 27 | AY29: =AY28+1/3 -> 9.6666667
A30: К4 | B30: 3720 | C30: =B30*8 -> 29760 | D30: 5220 | E30: =D30*8 -> 41760 | M30: Сложный | N30: 28 | O30: 4 | R30: Сложный | S30: 28 | T30: 4 | W30: Сложный | X30: 28 | Y30: =Y29+1/3 -> 10 | AB30: Сложный | AC30: 28 | AD30: =AD29+1/3 -> 10 | AG30: Сложный | AH30: 28 | AI30: =AI29+1/3 -> 10 | AL30: Сложный | AM30: 28 | AN30: =AN29+1/3 -> 10 | AQ30: Сложный | AR30: 28 | AS30: =AS29+1/3 -> 10 | AW30: Сложный | AX30: 28 | AY30: =AY29+1/3 -> 10
A31: К5 | B31: 4330 | C31: =B31*8 -> 34640 | D31: 6680 | E31: =D31*8 -> 53440 | M31: Сложный | N31: 29 | O31: 4 | R31: Сложный | S31: 29 | T31: 4 | W31: Сложный | X31: 29 | Y31: =Y30+1/3 -> 10.333333 | AB31: Сложный | AC31: 29 | AD31: =AD30+1/3 -> 10.333333 | AG31: Сложный | AH31: 29 | AI31: =AI30+1/3 -> 10.333333 | AL31: Сложный | AM31: 29 | AN31: =AN30+1/3 -> 10.333333 | AQ31: Сложный | AR31: 29 | AS31: =AS30+1/3 -> 10.333333 | AW31: Сложный | AX31: 29 | AY31: =AY30+1/3 -> 10.333333
M32: Сложный | N32: 30 | O32: 4 | R32: Сложный | S32: 30 | T32: 4 | W32: Сложный | X32: 30 | Y32: =Y31+1/3 -> 10.666667 | AB32: Сложный | AC32: 30 | AD32: =AD31+1/3 -> 10.666667 | AG32: Сложный | AH32: 30 | AI32: =AI31+1/3 -> 10.666667 | AL32: Сложный | AM32: 30 | AN32: =AN31+1/3 -> 10.666667 | AQ32: Сложный | AR32: 30 | AS32: =AS31+1/3 -> 10.666667 | AW32: Сложный | AX32: 30 | AY32: =AY31+1/3 -> 10.666667
A33: Внутренние ставки по грейдам на 2025 | D33: Внешние ставки по грейдам на 2025 (+ 10% от 2024 года) | G33: Внутренние ставки по грейдам на 2025 | J33: Внешние ставки по грейдам на 2025 (+ 10% от 2024 года) | M33: Сложный | N33: 31 | O33: 4 | R33: Сложный | S33: 31 | T33: 4 | W33: Сложный | X33: 31 | Y33: =Y32+1/3 -> 11 | AB33: Сложный | AC33: 31 | AD33: =AD32+1/3 -> 11 | AG33: Сложный | AH33: 31 | AI33: =AI32+1/3 -> 11 | AL33: Сложный | AM33: 31 | AN33: =AN32+1/3 -> 11 | AQ33: Сложный | AR33: 31 | AS33: =AS32+1/3 -> 11 | AW33: Сложный | AX33: 31 | AY33: =AY32+1/3 -> 11
A34: Грейд | B34: ч/ч | C34: ч/д | D34: ч/ч | E34: ч/д | G34: Грейд | H34: ч/ч | I34: ч/д | J34: ч/ч | K34: ч/д | M34: Сложный | N34: 32 | O34: 4 | R34: Сложный | S34: 32 | T34: 4 | W34: Сложный | X34: 32 | Y34: =Y33+1/3 -> 11.333333 | AB34: Сложный | AC34: 32 | AD34: =AD33+1/3 -> 11.333333 | AG34: Сложный | AH34: 32 | AI34: =AI33+1/3 -> 11.333333 | AL34: Сложный | AM34: 32 | AN34: =AN33+1/3 -> 11.333333 | AQ34: Сложный | AR34: 32 | AS34: =AS33+1/3 -> 11.333333 | AW34: Сложный | AX34: 32 | AY34: =AY33+1/3 -> 11.333333
A35: К1 | B35: =B27*1.1 -> 1551 | C35: =B35*8 -> 12408 | D35: =D27*1.1 -> 1991 | E35: =D35*8 -> 15928 | G35: К5 | H35: =VLOOKUP($G35,$A$35:$E$39,2,0) -> 4763 | I35: =VLOOKUP($G35,$A$35:$E$39,3,0) -> 38104 | J35: =VLOOKUP($G35,$A$35:$E$39,4,0) -> 7348 | K35: =VLOOKUP($G35,$A$35:$E$39,5,0) -> 58784 | M35: Сложный | N35: 33 | O35: 4 | R35: Сложный | S35: 33 | T35: 4 | W35: Сложный | X35: 33 | Y35: =Y34+1/3 -> 11.666667 | AB35: Сложный | AC35: 33 | AD35: =AD34+1/3 -> 11.666667 | AG35: Сложный | AH35: 33 | AI35: =AI34+1/3 -> 11.666667 | AL35: Сложный | AM35: 33 | AN35: =AN34+1/3 -> 11.666667 | AQ35: Сложный | AR35: 33 | AS35: =AS34+1/3 -> 11.666667 | AW35: Сложный | AX35: 33 | AY35: =AY34+1/3 -> 11.666667
A36: К2 | B36: =B28*1.1 -> 2376 | C36: =B36*8 -> 19008 | D36: =D28*1.1 -> 3179 | E36: =D36*8 -> 25432 | G36: К4 | H36: =VLOOKUP($G36,$A$35:$E$39,2,0) -> 4092 | I36: =VLOOKUP($G36,$A$35:$E$39,3,0) -> 32736 | J36: =VLOOKUP($G36,$A$35:$E$39,4,0) -> 5742 | K36: =VLOOKUP($G36,$A$35:$E$39,5,0) -> 45936 | M36: Сложный | N36: 34 | O36: 4 | R36: Сложный | S36: 34 | T36: 4 | W36: Сложный | X36: 34 | Y36: =Y35+1/3 -> 12 | AB36: Сложный | AC36: 34 | AD36: =AD35+1/3 -> 12 | AG36: Сложный | AH36: 34 | AI36: =AI35+1/3 -> 12 | AL36: Сложный | AM36: 34 | AN36: =AN35+1/3 -> 12 | AQ36: Сложный | AR36: 34 | AS36: =AS35+1/3 -> 12 | AW36: Сложный | AX36: 34 | AY36: =AY35+1/3 -> 12
A37: К3 | B37: =B29*1.1 -> 3058 | C37: =B37*8 -> 24464 | D37: =D29*1.1 -> 4301 | E37: =D37*8 -> 34408 | G37: К3 | H37: =VLOOKUP($G37,$A$35:$E$39,2,0) -> 3058 | I37: =VLOOKUP($G37,$A$35:$E$39,3,0) -> 24464 | J37: =VLOOKUP($G37,$A$35:$E$39,4,0) -> 4301 | K37: =VLOOKUP($G37,$A$35:$E$39,5,0) -> 34408 | M37: Сложный | N37: 35 | O37: 4 | R37: Сложный | S37: 35 | T37: 4 | W37: Сложный | X37: 35 | Y37: =Y36+1/3 -> 12.333333 | AB37: Сложный | AC37: 35 | AD37: =AD36+1/3 -> 12.333333 | AG37: Сложный | AH37: 35 | AI37: =AI36+1/3 -> 12.333333 | AL37: Сложный | AM37: 35 | AN37: =AN36+1/3 -> 12.333333 | AQ37: Сложный | AR37: 35 | AS37: =AS36+1/3 -> 12.333333 | AW37: Сложный | AX37: 35 | AY37: =AY36+1/3 -> 12.333333
A38: К4 | B38: =B30*1.1 -> 4092 | C38: =B38*8 -> 32736 | D38: =D30*1.1 -> 5742 | E38: =D38*8 -> 45936 | G38: К2 | H38: =VLOOKUP($G38,$A$35:$E$39,2,0) -> 2376 | I38: =VLOOKUP($G38,$A$35:$E$39,3,0) -> 19008 | J38: =VLOOKUP($G38,$A$35:$E$39,4,0) -> 3179 | K38: =VLOOKUP($G38,$A$35:$E$39,5,0) -> 25432 | M38: Сложный | N38: 36 | O38: 4 | R38: Сложный | S38: 36 | T38: 4 | W38: Сложный | X38: 36 | Y38: =Y37+1/3 -> 12.666667 | AB38: Сложный | AC38: 36 | AD38: =AD37+1/3 -> 12.666667 | AG38: Сложный | AH38: 36 | AI38: =AI37+1/3 -> 12.666667 | AL38: Сложный | AM38: 36 | AN38: =AN37+1/3 -> 12.666667 | AQ38: Сложный | AR38: 36 | AS38: =AS37+1/3 -> 12.666667 | AW38: Сложный | AX38: 36 | AY38: =AY37+1/3 -> 12.666667
A39: К5 | B39: =B31*1.1 -> 4763 | C39: =B39*8 -> 38104 | D39: =D31*1.1 -> 7348 | E39: =D39*8 -> 58784 | G39: К1 | H39: =VLOOKUP($G39,$A$35:$E$39,2,0) -> 1551 | I39: =VLOOKUP($G39,$A$35:$E$39,3,0) -> 12408 | J39: =VLOOKUP($G39,$A$35:$E$39,4,0) -> 1991 | K39: =VLOOKUP($G39,$A$35:$E$39,5,0) -> 15928 | M39: Сложный | N39: 37 | O39: 5 | R39: Сложный | S39: 37 | T39: 5 | W39: Сложный | X39: 37 | Y39: =Y38+1/3 -> 13 | AB39: Сложный | AC39: 37 | AD39: =AD38+1/3 -> 13 | AG39: Сложный | AH39: 37 | AI39: =AI38+1/3 -> 13 | AL39: Сложный | AM39: 37 | AN39: =AN38+1/3 -> 13 | AQ39: Сложный | AR39: 37 | AS39: =AS38+1/3 -> 13 | AW39: Сложный | AX39: 37 | AY39: =AY38+1/3 -> 13
M40: Сложный | N40: 38 | O40: 5 | R40: Сложный | S40: 38 | T40: 5 | W40: Сложный | X40: 38 | Y40: =Y39+1/3 -> 13.333333 | AB40: Сложный | AC40: 38 | AD40: =AD39+1/3 -> 13.333333 | AG40: Сложный | AH40: 38 | AI40: =AI39+1/3 -> 13.333333 | AL40: Сложный | AM40: 38 | AN40: =AN39+1/3 -> 13.333333 | AQ40: Сложный | AR40: 38 | AS40: =AS39+1/3 -> 13.333333 | AW40: Сложный | AX40: 38 | AY40: =AY39+1/3 -> 13.333333
...

Sheet Аналитика
B3: Трудозатраты в разрезе Этапов и их соотношение в проекте | C3: Соотношение к проекту | D3: Ч/Д на этап | E3: =Трудозатраты!I3 -> PM | F3: =Трудозатраты!J3 -> DS Senior | G3: =Трудозатраты!K3 -> DS middle | H3: =Трудозатраты!L3 -> Arch | I3: =Трудозатраты!M3 -> BI | J3: =Трудозатраты!N3 -> Data Engineer | K3: =Трудозатраты!O3 -> Ops (Dev/ML) | L3: =Трудозатраты!P3 -> BusinAnalust
B4: Этап 0. Подготовка инфраструктуры | C4: =D4/$D$11 -> 0.26578315 | D4: =SUM(E4:L4) -> 54.75 | E4: =SUM(Трудозатраты!I12:I16) -> 3 | F4: =SUM(Трудозатраты!J12:J16) -> 9.75 | G4: =SUM(Трудозатраты!K12:K16) -> 9 | H4: =SUM(Трудозатраты!L12:L16) -> 6.75 | I4: =SUM(Трудозатраты!M12:M16) -> 5.5 | J4: =SUM(Трудозатраты!N12:N16) -> 7.5 | K4: =SUM(Трудозатраты!O12:O16) -> 13.25 | L4: =SUM(Трудозатраты!P12:P16) -> 0
B5: Этап 1: Подготовка и планирование | C5: =D5/$D$11 -> 0.10679871 | D5: =SUM(E5:L5) -> 22 | E5: =SUM(Трудозатраты!I18) -> 3 | F5: =SUM(Трудозатраты!J18) -> 5 | G5: =SUM(Трудозатраты!K18) -> 5 | H5: =SUM(Трудозатраты!L18) -> 3 | I5: =SUM(Трудозатраты!M18) -> 1 | J5: =SUM(Трудозатраты!N18) -> 0 | K5: =SUM(Трудозатраты!O18) -> 0 | L5: =SUM(Трудозатраты!P18) -> 5
B6: Этап 2: Сбор и анализ данных | C6: =D6/$D$11 -> 0.3021918 | D6: =SUM(E6:L6) -> 62.25 | E6: =SUM(Трудозатраты!I20:I26) -> 2.25 | F6: =SUM(Трудозатраты!J20:J26) -> 19 | G6: =SUM(Трудозатраты!K20:K26) -> 16 | H6: =SUM(Трудозатраты!L20:L26) -> 6 | I6: =SUM(Трудозатраты!M20:M26) -> 1 | J6: =SUM(Трудозатраты!N20:N26) -> 15 | K6: =SUM(Трудозатраты!O20:O26) -> 1 | L6: =SUM(Трудозатраты!P20:P26) -> 2
B7: Этап 3: Моделирование | C7: =D7/$D$11 -> 0.13107114 | D7: =SUM(E7:L7) -> 27 | E7: =SUM(Трудозатраты!I28:I30) -> 1 | F7: =SUM(Трудозатраты!J28:J30) -> 8 | G7: =SUM(Трудозатраты!K28:K30) -> 5 | H7: =SUM(Трудозатраты!L28:L30) -> 1 | I7: =SUM(Трудозатраты!M28:M30) -> 3 | J7: =SUM(Трудозатраты!N28:N30) -> 2 | K7: =SUM(Трудозатраты!O28:O30) -> 7 | L7: =SUM(Трудозатраты!P28:P30) -> 0
B8: Этап 4: Пуско-наладочные испытания и оптимизация | C8: =D8/$D$11 -> 0.090536178 | D8: =SUM(E8:L8) -> 18.65 | E8: =SUM(Трудозатраты!I32:I34) -> 3.1 | F8: =SUM(Трудозатраты!J32:J34) -> 3.25 | G8: =SUM(Трудозатраты!K32:K34) -> 4 | H8: =SUM(Трудозатраты!L32:L34) -> 3.1 | I8: =SUM(Трудозатраты!M32:M34) -> 3.1 | J8: =SUM(Трудозатраты!N32:N34) -> 0 | K8: =SUM(Трудозатраты!O32:O34) -> 2.1 | L8: =SUM(Трудозатраты!P32:P34) -> 0
B9: Этап 5: Обучение и Документация | C9: =D9/$D$11 -> 0.049758489 | D9: =SUM(E9:L9) -> 10.25 | E9: =SUM(Трудозатраты!I36:I38) -> 2 | F9: =SUM(Трудозатраты!J36:J38) -> 1.25 | G9: =SUM(Трудозатраты!K36:K38) -> 3 | H9: =SUM(Трудозатраты!L36:L38) -> 0.25 | I9: =SUM(Трудозатраты!M36:M38) -> 0.25 | J9: =SUM(Трудозатраты!N36:N38) -> 0.25 | K9: =SUM(Трудозатраты!O36:O38) -> 1.75 | L9: =SUM(Трудозатраты!P36:P38) -> 1.5
B10: Этап 6: Завершение проекта | C10: =D10/$D$11 -> 0.053860531 | D10: =SUM(E10:L10) -> 11.095 | E10: =SUM(Трудозатраты!I40:I42) -> 2.63 | F10: =SUM(Трудозатраты!J40:J42) -> 2.725 | G10: =SUM(Трудозатраты!K40:K42) -> 1.575 | H10: =SUM(Трудозатраты!L40:L42) -> 0.63 | I10: =SUM(Трудозатраты!M40:M42) -> 0.68 | J10: =SUM(Трудозатраты!N40:N42) -> 0.8625 | K10: =SUM(Трудозатраты!O40:O42) -> 0.5925 | L10: =SUM(Трудозатраты!P40:P42) -> 1.4
B11: Итого: | C11: =D11/$D$11 -> 1 | D11: =SUM(E11:L11) -> 205.995 | E11: =Трудозатраты!I43 -> 16.98 | F11: =Трудозатраты!J43 -> 48.975 | G11: =Трудозатраты!K43 -> 43.575 | H11: =Трудозатраты!L43 -> 20.73 | I11: =Трудозатраты!M43 -> 14.53 | J11: =Трудозатраты!N43 -> 25.6125 | K11: =Трудозатраты!O43 -> 25.6925 | L11: =Трудозатраты!P43 -> 9.9
B37: Бизнес домены данных. Указать количество в разрезе их сложности. | C37: Бизнес Домен - область бизнеса, которая предлагается в рамках исследования. В ERP это модули программы. Например: транзакции, трафик, блок видеоданных, видеоряд, количество технологических переделов, виды продукции.
B38: Количество и сложность источников данных (API, РестФулл, …). Указать количество в разрезе их сложности. | C38: (API, РестФулл, …)
B39: Уровень сложности проекта. Указать уровень сложности.
B40: Количество, тип и сложность модели. Указать количество в разрезе их сложности.
B41: По количеству WorkFlow процессов. Указать количество в разрезе их сложности.
